INFO 2019-07-18 11:14:43,926 basehttp 154 "GET /admin/ HTTP/1.1" 200 8784
WARNING 2019-07-18 11:14:44,105 log 228 Not Found: /favicon.ico
WARNING 2019-07-18 11:14:44,106 basehttp 154 "GET /favicon.ico HTTP/1.1" 404 2187
INFO 2019-07-18 11:14:50,614 views 91 /polls/get_man/
INFO 2019-07-18 11:14:50,620 basehttp 154 "GET /polls/get_man/ HTTP/1.1" 200 338
INFO 2019-07-18 11:14:50,645 basehttp 154 "GET /static/js/vue.min.js HTTP/1.1" 200 70998
INFO 2019-07-18 11:14:50,646 basehttp 154 "GET /static/js/man.js HTTP/1.1" 200 37
INFO 2019-07-18 11:14:50,659 basehttp 154 "GET /static/css/style.css HTTP/1.1" 304 0
INFO 2019-07-18 11:14:50,700 basehttp 154 "GET /static/images/background.png HTTP/1.1" 200 1724105
INFO 2019-07-18 11:18:08,187 views 91 /polls/get_man/
INFO 2019-07-18 11:18:08,195 views 92 False
INFO 2019-07-18 11:18:08,201 basehttp 154 "GET /polls/get_man/ HTTP/1.1" 200 338
INFO 2019-07-18 11:18:08,237 basehttp 154 "GET /static/images/favicon.ico HTTP/1.1" 200 1459819
INFO 2019-07-18 11:19:47,825 views 91 /polls/get_man/
INFO 2019-07-18 11:19:47,825 views 92 False
INFO 2019-07-18 11:19:47,825 views 93 {'ALLUSERSPROFILE': 'C:\\ProgramData', 'APPDATA': 'C:\\Users\\ŒÃ—ß∫¿\\AppData\\Roaming', 'COMMONPROGRAMFILES': 'C:\\Program Files\\Common Files', 'COMMONPROGRAMFILES(X86)': 'C:\\Program Files (x86)\\Common Files', 'COMMONPROGRAMW6432': 'C:\\Program Files\\Common Files', 'COMPUTERNAME': 'XUEHAOWENG', 'COMSPEC': 'C:\\WINDOWS\\system32\\cmd.exe', 'DRIVERDATA': 'C:\\Windows\\System32\\Drivers\\DriverData', 'FPS_BROWSER_APP_PROFILE_STRING': 'Internet Explorer', 'FPS_BROWSER_USER_PROFILE_STRING': 'Default', 'HOMEDRIVE': 'C:', 'HOMEPATH': '\\Users\\ŒÃ—ß∫¿', 'LOCALAPPDATA': 'C:\\Users\\ŒÃ—ß∫¿\\AppData\\Local', 'LOGONSERVER': '\\\\XUEHAOWENG', 'MYSQL': 'C:\\Mysql\\mysql-8.0.13-winx64\\bin', 'NUMBER_OF_PROCESSORS': '8', 'ONEDRIVE': 'C:\\Users\\ŒÃ—ß∫¿\\OneDrive', 'OS': 'Windows_NT', 'PATH': 'C:\\Python\\Python36;C:\\Python27\\;C:\\Python27\\Scripts;C:\\Program Files (x86)\\Intel\\iCLS Client\\;C:\\Program Files\\Intel\\iCLS Client\\;C:\\Windows\\system32;C:\\Windows;C:\\Windows\\System32\\Wbem;C:\\Windows\\System32\\WindowsPowerShell\\v1.0\\;C:\\Program Files (x86)\\Intel\\Intel(R) Management Engine Components\\DAL;C:\\Program Files\\Intel\\Intel(R) Management Engine Components\\DAL;C:\\Program Files (x86)\\Intel\\Intel(R) Management Engine Components\\IPT;C:\\Program Files\\Intel\\Intel(R) Management Engine Components\\IPT;C:\\Program Files (x86)\\NVIDIA Corporation\\PhysX\\Common;C:\\Program Files\\Intel\\WiFi\\bin\\;C:\\Program Files\\Common Files\\Intel\\WirelessCommon\\;C:\\WINDOWS\\system32;C:\\WINDOWS;C:\\WINDOWS\\System32\\Wbem;C:\\WINDOWS\\System32\\WindowsPowerShell\\v1.0\\;C:\\WINDOWS\\System32\\OpenSSH\\;D:\\shortcut;C:\\Program Files\\Microsoft VS Code\\bin;C:\\Program Files\\;D:\\Git\\cmd;D:\\wxh\\tools\\node\\;C:\\Users\\ŒÃ—ß∫¿\\AppData\\Local\\Programs\\Python\\Python36\\Scripts\\;C:\\Users\\ŒÃ—ß∫¿\\AppData\\Local\\Programs\\Python\\Python36\\;C:\\Users\\ŒÃ—ß∫¿\\AppData\\Local\\Microsoft\\WindowsApps;D:\\wxh\\tools\\Microsoft VS Code\\bin;C:\\Users\\ŒÃ—ß∫¿\\AppData\\Local\\GitHubDesktop\\bin;D:\\shortcut;D:\\PyCharm 2019.1.3\\bin;;C:\\Mysql\\mysql-8.0.13-winx64\\bin;C:\\Program Files\\JetBrains\\PyCharm 2018.3.1\\bin;C:\\Python\\Python36\\Lib\\site-packages\\django;C:\\Python27\\Lib\\site-packages\\django;C:\\Python\\Python36\\;C:\\Python\\Python36\\Scripts;C:\\seleniumdirver\\chromedriver.exe;C:\\seleniumdirver\\phantomjs-2.1.1-windows\\bin\\phantomjs.exe;C:\\Users\\ŒÃ—ß∫¿\\AppData\\Roaming\\npm;C:\\Users\\ŒÃ—ß∫¿\\AppData\\Local\\Programs\\Python\\Python36\\lib\\site-packages\\numpy\\.libs;C:\\Users\\ŒÃ—ß∫¿\\AppData\\Local\\Programs\\Python\\Python36\\lib\\site-packages\\numpy\\.libs', 'PATHEXT': '.COM;.EXE;.BAT;.CMD;.VBS;.VBE;.JS;.JSE;.WSF;.WSH;.MSC', 'PROCESSOR_ARCHITECTURE': 'AMD64', 'PROCESSOR_IDENTIFIER': 'Intel64 Family 6 Model 142 Stepping 10, GenuineIntel', 'PROCESSOR_LEVEL': '6', 'PROCESSOR_REVISION': '8e0a', 'PROGRAMDATA': 'C:\\ProgramData', 'PROGRAMFILES': 'C:\\Program Files', 'PROGRAMFILES(X86)': 'C:\\Program Files (x86)', 'PROGRAMW6432': 'C:\\Program Files', 'PSMODULEPATH': 'C:\\Program Files\\WindowsPowerShell\\Modules;C:\\WINDOWS\\system32\\WindowsPowerShell\\v1.0\\Modules', 'PUBLIC': 'C:\\Users\\Public', 'PYCHARM': 'D:\\PyCharm 2019.1.3\\bin;', 'PYCHARM_DISPLAY_PORT': '4390', 'PYCHARM_HOSTED': '1', 'PYTHONIOENCODING': 'UTF-8', 'PYTHONPATH': 'D:\\wxh\\mysite;D:\\wxh\\mysite\\static;D:\\PyCharm 2019.1.3\\helpers\\pycharm_matplotlib_backend;D:\\PyCharm 2019.1.3\\helpers\\pycharm_display', 'PYTHONUNBUFFERED': '1', 'SESSIONNAME': 'Console', 'SYSTEMDRIVE': 'C:', 'SYSTEMROOT': 'C:\\WINDOWS', 'TEMP': 'C:\\Users\\ŒÃ—ß∫¿\\AppData\\Local\\Temp', 'TMP': 'C:\\Users\\ŒÃ—ß∫¿\\AppData\\Local\\Temp', 'USERDOMAIN': 'XUEHAOWENG', 'USERDOMAIN_ROAMINGPROFILE': 'XUEHAOWENG', 'USERNAME': 'ŒÃ—ß∫¿', 'USERPROFILE': 'C:\\Users\\ŒÃ—ß∫¿', 'WINDIR': 'C:\\WINDOWS', 'DJANGO_SETTINGS_MODULE': 'mysite.settings', 'RUN_MAIN': 'true', 'SERVER_NAME': 'xuehaoWeng', 'GATEWAY_INTERFACE': 'CGI/1.1', 'SERVER_PORT': '9000', 'REMOTE_HOST': '', 'CONTENT_LENGTH': '', 'SCRIPT_NAME': '', 'SERVER_PROTOCOL': 'HTTP/1.1', 'SERVER_SOFTWARE': 'WSGIServer/0.2', 'REQUEST_METHOD': 'GET', 'PATH_INFO': '/polls/get_man/', 'QUERY_STRING': '', 'REMOTE_ADDR': '127.0.0.1', 'CONTENT_TYPE': 'text/plain', 'HTTP_HOST': '127.0.0.1:9000', 'HTTP_CONNECTION': 'keep-alive', 'HTTP_PRAGMA': 'no-cache', 'HTTP_CACHE_CONTROL': 'no-cache', 'HTTP_UPGRADE_INSECURE_REQUESTS': '1', 'HTTP_USER_AGENT': 'Mozilla/5.0 (Windows NT 10.0; WOW64) AppleWebKit/537.36 (KHTML, like Gecko) Chrome/75.0.3770.100 Safari/537.36', 'HTTP_ACCEPT': 'text/html,application/xhtml+xml,application/xml;q=0.9,image/webp,image/apng,*/*;q=0.8,application/signed-exchange;v=b3', 'HTTP_ACCEPT_ENCODING': 'gzip, deflate, br', 'HTTP_ACCEPT_LANGUAGE': 'zh-CN,zh;q=0.9', 'HTTP_COOKIE': 'csrftoken=lniJGlOmYFoJl73WncIC04fLMHq7LeE8gJvyI068r4UoPIaqa9Hhjd6ZLxW03bgc; sessionid=8ukmepfgnk98ok5v8467337rgnhr9f90', 'wsgi.input': <django.core.handlers.wsgi.LimitedStream object at 0x000002107CE002B0>, 'wsgi.errors': <_io.TextIOWrapper name='<stderr>' mode='w' encoding='UTF-8'>, 'wsgi.version': (1, 0), 'wsgi.run_once': False, 'wsgi.url_scheme': 'http', 'wsgi.multithread': True, 'wsgi.multiprocess': False, 'wsgi.file_wrapper': <class 'wsgiref.util.FileWrapper'>}
INFO 2019-07-18 11:19:47,840 basehttp 154 "GET /polls/get_man/ HTTP/1.1" 200 338
INFO 2019-07-18 11:19:47,851 basehttp 154 "GET /static/css/style.css HTTP/1.1" 200 203
INFO 2019-07-18 11:19:47,852 basehttp 154 "GET /static/js/man.js HTTP/1.1" 200 37
INFO 2019-07-18 11:19:47,853 basehttp 154 "GET /static/js/vue.min.js HTTP/1.1" 200 70998
INFO 2019-07-18 11:19:47,872 basehttp 154 "GET /static/images/background.png HTTP/1.1" 200 1724105
INFO 2019-07-18 11:19:47,895 basehttp 154 "GET /static/images/favicon.ico HTTP/1.1" 200 1459819
INFO 2019-07-18 11:21:19,336 views 92 «Î«Û¬∑æ∂£∫/polls/get_man/
INFO 2019-07-18 11:21:19,336 views 93 «Î«Û «∑Ò «https£∫False
INFO 2019-07-18 11:21:19,336 views 94 «Î«Ûheaders:{'ALLUSERSPROFILE': 'C:\\ProgramData', 'APPDATA': 'C:\\Users\\ŒÃ—ß∫¿\\AppData\\Roaming', 'COMMONPROGRAMFILES': 'C:\\Program Files\\Common Files', 'COMMONPROGRAMFILES(X86)': 'C:\\Program Files (x86)\\Common Files', 'COMMONPROGRAMW6432': 'C:\\Program Files\\Common Files', 'COMPUTERNAME': 'XUEHAOWENG', 'COMSPEC': 'C:\\WINDOWS\\system32\\cmd.exe', 'DRIVERDATA': 'C:\\Windows\\System32\\Drivers\\DriverData', 'FPS_BROWSER_APP_PROFILE_STRING': 'Internet Explorer', 'FPS_BROWSER_USER_PROFILE_STRING': 'Default', 'HOMEDRIVE': 'C:', 'HOMEPATH': '\\Users\\ŒÃ—ß∫¿', 'LOCALAPPDATA': 'C:\\Users\\ŒÃ—ß∫¿\\AppData\\Local', 'LOGONSERVER': '\\\\XUEHAOWENG', 'MYSQL': 'C:\\Mysql\\mysql-8.0.13-winx64\\bin', 'NUMBER_OF_PROCESSORS': '8', 'ONEDRIVE': 'C:\\Users\\ŒÃ—ß∫¿\\OneDrive', 'OS': 'Windows_NT', 'PATH': 'C:\\Python\\Python36;C:\\Python27\\;C:\\Python27\\Scripts;C:\\Program Files (x86)\\Intel\\iCLS Client\\;C:\\Program Files\\Intel\\iCLS Client\\;C:\\Windows\\system32;C:\\Windows;C:\\Windows\\System32\\Wbem;C:\\Windows\\System32\\WindowsPowerShell\\v1.0\\;C:\\Program Files (x86)\\Intel\\Intel(R) Management Engine Components\\DAL;C:\\Program Files\\Intel\\Intel(R) Management Engine Components\\DAL;C:\\Program Files (x86)\\Intel\\Intel(R) Management Engine Components\\IPT;C:\\Program Files\\Intel\\Intel(R) Management Engine Components\\IPT;C:\\Program Files (x86)\\NVIDIA Corporation\\PhysX\\Common;C:\\Program Files\\Intel\\WiFi\\bin\\;C:\\Program Files\\Common Files\\Intel\\WirelessCommon\\;C:\\WINDOWS\\system32;C:\\WINDOWS;C:\\WINDOWS\\System32\\Wbem;C:\\WINDOWS\\System32\\WindowsPowerShell\\v1.0\\;C:\\WINDOWS\\System32\\OpenSSH\\;D:\\shortcut;C:\\Program Files\\Microsoft VS Code\\bin;C:\\Program Files\\;D:\\Git\\cmd;D:\\wxh\\tools\\node\\;C:\\Users\\ŒÃ—ß∫¿\\AppData\\Local\\Programs\\Python\\Python36\\Scripts\\;C:\\Users\\ŒÃ—ß∫¿\\AppData\\Local\\Programs\\Python\\Python36\\;C:\\Users\\ŒÃ—ß∫¿\\AppData\\Local\\Microsoft\\WindowsApps;D:\\wxh\\tools\\Microsoft VS Code\\bin;C:\\Users\\ŒÃ—ß∫¿\\AppData\\Local\\GitHubDesktop\\bin;D:\\shortcut;D:\\PyCharm 2019.1.3\\bin;;C:\\Mysql\\mysql-8.0.13-winx64\\bin;C:\\Program Files\\JetBrains\\PyCharm 2018.3.1\\bin;C:\\Python\\Python36\\Lib\\site-packages\\django;C:\\Python27\\Lib\\site-packages\\django;C:\\Python\\Python36\\;C:\\Python\\Python36\\Scripts;C:\\seleniumdirver\\chromedriver.exe;C:\\seleniumdirver\\phantomjs-2.1.1-windows\\bin\\phantomjs.exe;C:\\Users\\ŒÃ—ß∫¿\\AppData\\Roaming\\npm;C:\\Users\\ŒÃ—ß∫¿\\AppData\\Local\\Programs\\Python\\Python36\\lib\\site-packages\\numpy\\.libs;C:\\Users\\ŒÃ—ß∫¿\\AppData\\Local\\Programs\\Python\\Python36\\lib\\site-packages\\numpy\\.libs', 'PATHEXT': '.COM;.EXE;.BAT;.CMD;.VBS;.VBE;.JS;.JSE;.WSF;.WSH;.MSC', 'PROCESSOR_ARCHITECTURE': 'AMD64', 'PROCESSOR_IDENTIFIER': 'Intel64 Family 6 Model 142 Stepping 10, GenuineIntel', 'PROCESSOR_LEVEL': '6', 'PROCESSOR_REVISION': '8e0a', 'PROGRAMDATA': 'C:\\ProgramData', 'PROGRAMFILES': 'C:\\Program Files', 'PROGRAMFILES(X86)': 'C:\\Program Files (x86)', 'PROGRAMW6432': 'C:\\Program Files', 'PSMODULEPATH': 'C:\\Program Files\\WindowsPowerShell\\Modules;C:\\WINDOWS\\system32\\WindowsPowerShell\\v1.0\\Modules', 'PUBLIC': 'C:\\Users\\Public', 'PYCHARM': 'D:\\PyCharm 2019.1.3\\bin;', 'PYCHARM_DISPLAY_PORT': '4390', 'PYCHARM_HOSTED': '1', 'PYTHONIOENCODING': 'UTF-8', 'PYTHONPATH': 'D:\\wxh\\mysite;D:\\wxh\\mysite\\static;D:\\PyCharm 2019.1.3\\helpers\\pycharm_matplotlib_backend;D:\\PyCharm 2019.1.3\\helpers\\pycharm_display', 'PYTHONUNBUFFERED': '1', 'SESSIONNAME': 'Console', 'SYSTEMDRIVE': 'C:', 'SYSTEMROOT': 'C:\\WINDOWS', 'TEMP': 'C:\\Users\\ŒÃ—ß∫¿\\AppData\\Local\\Temp', 'TMP': 'C:\\Users\\ŒÃ—ß∫¿\\AppData\\Local\\Temp', 'USERDOMAIN': 'XUEHAOWENG', 'USERDOMAIN_ROAMINGPROFILE': 'XUEHAOWENG', 'USERNAME': 'ŒÃ—ß∫¿', 'USERPROFILE': 'C:\\Users\\ŒÃ—ß∫¿', 'WINDIR': 'C:\\WINDOWS', 'DJANGO_SETTINGS_MODULE': 'mysite.settings', 'RUN_MAIN': 'true', 'SERVER_NAME': 'xuehaoWeng', 'GATEWAY_INTERFACE': 'CGI/1.1', 'SERVER_PORT': '9000', 'REMOTE_HOST': '', 'CONTENT_LENGTH': '', 'SCRIPT_NAME': '', 'SERVER_PROTOCOL': 'HTTP/1.1', 'SERVER_SOFTWARE': 'WSGIServer/0.2', 'REQUEST_METHOD': 'GET', 'PATH_INFO': '/polls/get_man/', 'QUERY_STRING': '', 'REMOTE_ADDR': '127.0.0.1', 'CONTENT_TYPE': 'text/plain', 'HTTP_HOST': '127.0.0.1:9000', 'HTTP_CONNECTION': 'keep-alive', 'HTTP_PRAGMA': 'no-cache', 'HTTP_CACHE_CONTROL': 'no-cache', 'HTTP_UPGRADE_INSECURE_REQUESTS': '1', 'HTTP_USER_AGENT': 'Mozilla/5.0 (Windows NT 10.0; WOW64) AppleWebKit/537.36 (KHTML, like Gecko) Chrome/75.0.3770.100 Safari/537.36', 'HTTP_ACCEPT': 'text/html,application/xhtml+xml,application/xml;q=0.9,image/webp,image/apng,*/*;q=0.8,application/signed-exchange;v=b3', 'HTTP_ACCEPT_ENCODING': 'gzip, deflate, br', 'HTTP_ACCEPT_LANGUAGE': 'zh-CN,zh;q=0.9', 'HTTP_COOKIE': 'csrftoken=lniJGlOmYFoJl73WncIC04fLMHq7LeE8gJvyI068r4UoPIaqa9Hhjd6ZLxW03bgc; sessionid=8ukmepfgnk98ok5v8467337rgnhr9f90', 'wsgi.input': <django.core.handlers.wsgi.LimitedStream object at 0x000002577BAE2860>, 'wsgi.errors': <_io.TextIOWrapper name='<stderr>' mode='w' encoding='UTF-8'>, 'wsgi.version': (1, 0), 'wsgi.run_once': False, 'wsgi.url_scheme': 'http', 'wsgi.multithread': True, 'wsgi.multiprocess': False, 'wsgi.file_wrapper': <class 'wsgiref.util.FileWrapper'>}
INFO 2019-07-18 11:21:19,344 basehttp 154 "GET /polls/get_man/ HTTP/1.1" 200 338
INFO 2019-07-18 11:21:19,357 basehttp 154 "GET /static/css/style.css HTTP/1.1" 200 203
INFO 2019-07-18 11:21:19,358 basehttp 154 "GET /static/js/man.js HTTP/1.1" 200 37
INFO 2019-07-18 11:21:19,358 basehttp 154 "GET /static/js/vue.min.js HTTP/1.1" 200 70998
INFO 2019-07-18 11:21:19,381 basehttp 154 "GET /static/images/background.png HTTP/1.1" 200 1724105
INFO 2019-07-18 11:21:19,404 basehttp 154 "GET /static/images/favicon.ico HTTP/1.1" 200 1459819
INFO 2019-07-18 11:21:47,987 views 92 «Î«Û¬∑æ∂£∫/polls/get_man/
INFO 2019-07-18 11:21:47,987 views 93 «Î«Û «∑Ò «https£∫False
INFO 2019-07-18 11:21:47,987 views 94 «Î«Ûheaders:{'ALLUSERSPROFILE': 'C:\\ProgramData', 'APPDATA': 'C:\\Users\\ŒÃ—ß∫¿\\AppData\\Roaming', 'COMMONPROGRAMFILES': 'C:\\Program Files\\Common Files', 'COMMONPROGRAMFILES(X86)': 'C:\\Program Files (x86)\\Common Files', 'COMMONPROGRAMW6432': 'C:\\Program Files\\Common Files', 'COMPUTERNAME': 'XUEHAOWENG', 'COMSPEC': 'C:\\WINDOWS\\system32\\cmd.exe', 'DRIVERDATA': 'C:\\Windows\\System32\\Drivers\\DriverData', 'FPS_BROWSER_APP_PROFILE_STRING': 'Internet Explorer', 'FPS_BROWSER_USER_PROFILE_STRING': 'Default', 'HOMEDRIVE': 'C:', 'HOMEPATH': '\\Users\\ŒÃ—ß∫¿', 'LOCALAPPDATA': 'C:\\Users\\ŒÃ—ß∫¿\\AppData\\Local', 'LOGONSERVER': '\\\\XUEHAOWENG', 'MYSQL': 'C:\\Mysql\\mysql-8.0.13-winx64\\bin', 'NUMBER_OF_PROCESSORS': '8', 'ONEDRIVE': 'C:\\Users\\ŒÃ—ß∫¿\\OneDrive', 'OS': 'Windows_NT', 'PATH': 'C:\\Python\\Python36;C:\\Python27\\;C:\\Python27\\Scripts;C:\\Program Files (x86)\\Intel\\iCLS Client\\;C:\\Program Files\\Intel\\iCLS Client\\;C:\\Windows\\system32;C:\\Windows;C:\\Windows\\System32\\Wbem;C:\\Windows\\System32\\WindowsPowerShell\\v1.0\\;C:\\Program Files (x86)\\Intel\\Intel(R) Management Engine Components\\DAL;C:\\Program Files\\Intel\\Intel(R) Management Engine Components\\DAL;C:\\Program Files (x86)\\Intel\\Intel(R) Management Engine Components\\IPT;C:\\Program Files\\Intel\\Intel(R) Management Engine Components\\IPT;C:\\Program Files (x86)\\NVIDIA Corporation\\PhysX\\Common;C:\\Program Files\\Intel\\WiFi\\bin\\;C:\\Program Files\\Common Files\\Intel\\WirelessCommon\\;C:\\WINDOWS\\system32;C:\\WINDOWS;C:\\WINDOWS\\System32\\Wbem;C:\\WINDOWS\\System32\\WindowsPowerShell\\v1.0\\;C:\\WINDOWS\\System32\\OpenSSH\\;D:\\shortcut;C:\\Program Files\\Microsoft VS Code\\bin;C:\\Program Files\\;D:\\Git\\cmd;D:\\wxh\\tools\\node\\;C:\\Users\\ŒÃ—ß∫¿\\AppData\\Local\\Programs\\Python\\Python36\\Scripts\\;C:\\Users\\ŒÃ—ß∫¿\\AppData\\Local\\Programs\\Python\\Python36\\;C:\\Users\\ŒÃ—ß∫¿\\AppData\\Local\\Microsoft\\WindowsApps;D:\\wxh\\tools\\Microsoft VS Code\\bin;C:\\Users\\ŒÃ—ß∫¿\\AppData\\Local\\GitHubDesktop\\bin;D:\\shortcut;D:\\PyCharm 2019.1.3\\bin;;C:\\Mysql\\mysql-8.0.13-winx64\\bin;C:\\Program Files\\JetBrains\\PyCharm 2018.3.1\\bin;C:\\Python\\Python36\\Lib\\site-packages\\django;C:\\Python27\\Lib\\site-packages\\django;C:\\Python\\Python36\\;C:\\Python\\Python36\\Scripts;C:\\seleniumdirver\\chromedriver.exe;C:\\seleniumdirver\\phantomjs-2.1.1-windows\\bin\\phantomjs.exe;C:\\Users\\ŒÃ—ß∫¿\\AppData\\Roaming\\npm;C:\\Users\\ŒÃ—ß∫¿\\AppData\\Local\\Programs\\Python\\Python36\\lib\\site-packages\\numpy\\.libs;C:\\Users\\ŒÃ—ß∫¿\\AppData\\Local\\Programs\\Python\\Python36\\lib\\site-packages\\numpy\\.libs', 'PATHEXT': '.COM;.EXE;.BAT;.CMD;.VBS;.VBE;.JS;.JSE;.WSF;.WSH;.MSC', 'PROCESSOR_ARCHITECTURE': 'AMD64', 'PROCESSOR_IDENTIFIER': 'Intel64 Family 6 Model 142 Stepping 10, GenuineIntel', 'PROCESSOR_LEVEL': '6', 'PROCESSOR_REVISION': '8e0a', 'PROGRAMDATA': 'C:\\ProgramData', 'PROGRAMFILES': 'C:\\Program Files', 'PROGRAMFILES(X86)': 'C:\\Program Files (x86)', 'PROGRAMW6432': 'C:\\Program Files', 'PSMODULEPATH': 'C:\\Program Files\\WindowsPowerShell\\Modules;C:\\WINDOWS\\system32\\WindowsPowerShell\\v1.0\\Modules', 'PUBLIC': 'C:\\Users\\Public', 'PYCHARM': 'D:\\PyCharm 2019.1.3\\bin;', 'PYCHARM_DISPLAY_PORT': '4390', 'PYCHARM_HOSTED': '1', 'PYTHONIOENCODING': 'UTF-8', 'PYTHONPATH': 'D:\\wxh\\mysite;D:\\wxh\\mysite\\static;D:\\PyCharm 2019.1.3\\helpers\\pycharm_matplotlib_backend;D:\\PyCharm 2019.1.3\\helpers\\pycharm_display', 'PYTHONUNBUFFERED': '1', 'SESSIONNAME': 'Console', 'SYSTEMDRIVE': 'C:', 'SYSTEMROOT': 'C:\\WINDOWS', 'TEMP': 'C:\\Users\\ŒÃ—ß∫¿\\AppData\\Local\\Temp', 'TMP': 'C:\\Users\\ŒÃ—ß∫¿\\AppData\\Local\\Temp', 'USERDOMAIN': 'XUEHAOWENG', 'USERDOMAIN_ROAMINGPROFILE': 'XUEHAOWENG', 'USERNAME': 'ŒÃ—ß∫¿', 'USERPROFILE': 'C:\\Users\\ŒÃ—ß∫¿', 'WINDIR': 'C:\\WINDOWS', 'DJANGO_SETTINGS_MODULE': 'mysite.settings', 'RUN_MAIN': 'true', 'SERVER_NAME': 'xuehaoWeng', 'GATEWAY_INTERFACE': 'CGI/1.1', 'SERVER_PORT': '9000', 'REMOTE_HOST': '', 'CONTENT_LENGTH': '', 'SCRIPT_NAME': '', 'SERVER_PROTOCOL': 'HTTP/1.1', 'SERVER_SOFTWARE': 'WSGIServer/0.2', 'REQUEST_METHOD': 'GET', 'PATH_INFO': '/polls/get_man/', 'QUERY_STRING': '', 'REMOTE_ADDR': '127.0.0.1', 'CONTENT_TYPE': 'text/plain', 'HTTP_HOST': '127.0.0.1:9000', 'HTTP_CONNECTION': 'keep-alive', 'HTTP_CACHE_CONTROL': 'max-age=0', 'HTTP_UPGRADE_INSECURE_REQUESTS': '1', 'HTTP_USER_AGENT': 'Mozilla/5.0 (Windows NT 10.0; WOW64) AppleWebKit/537.36 (KHTML, like Gecko) Chrome/75.0.3770.100 Safari/537.36', 'HTTP_ACCEPT': 'text/html,application/xhtml+xml,application/xml;q=0.9,image/webp,image/apng,*/*;q=0.8,application/signed-exchange;v=b3', 'HTTP_ACCEPT_ENCODING': 'gzip, deflate, br', 'HTTP_ACCEPT_LANGUAGE': 'zh-CN,zh;q=0.9', 'HTTP_COOKIE': 'csrftoken=lniJGlOmYFoJl73WncIC04fLMHq7LeE8gJvyI068r4UoPIaqa9Hhjd6ZLxW03bgc; sessionid=8ukmepfgnk98ok5v8467337rgnhr9f90', 'wsgi.input': <django.core.handlers.wsgi.LimitedStream object at 0x000002577BF09F60>, 'wsgi.errors': <_io.TextIOWrapper name='<stderr>' mode='w' encoding='UTF-8'>, 'wsgi.version': (1, 0), 'wsgi.run_once': False, 'wsgi.url_scheme': 'http', 'wsgi.multithread': True, 'wsgi.multiprocess': False, 'wsgi.file_wrapper': <class 'wsgiref.util.FileWrapper'>}
INFO 2019-07-18 11:21:47,992 basehttp 154 "GET /polls/get_man/ HTTP/1.1" 200 338
INFO 2019-07-18 11:21:48,050 basehttp 154 "GET /static/images/favicon.ico HTTP/1.1" 200 1459819
INFO 2019-07-18 11:22:57,820 views 92 «Î«Û¬∑æ∂£∫/polls/get_man/
INFO 2019-07-18 11:22:57,821 views 93 «Î«Û «∑Ò «https£∫False
INFO 2019-07-18 11:22:57,821 views 94 «Î«Ûheaders:{'ALLUSERSPROFILE': 'C:\\ProgramData', 'APPDATA': 'C:\\Users\\ŒÃ—ß∫¿\\AppData\\Roaming', 'COMMONPROGRAMFILES': 'C:\\Program Files\\Common Files', 'COMMONPROGRAMFILES(X86)': 'C:\\Program Files (x86)\\Common Files', 'COMMONPROGRAMW6432': 'C:\\Program Files\\Common Files', 'COMPUTERNAME': 'XUEHAOWENG', 'COMSPEC': 'C:\\WINDOWS\\system32\\cmd.exe', 'DRIVERDATA': 'C:\\Windows\\System32\\Drivers\\DriverData', 'FPS_BROWSER_APP_PROFILE_STRING': 'Internet Explorer', 'FPS_BROWSER_USER_PROFILE_STRING': 'Default', 'HOMEDRIVE': 'C:', 'HOMEPATH': '\\Users\\ŒÃ—ß∫¿', 'LOCALAPPDATA': 'C:\\Users\\ŒÃ—ß∫¿\\AppData\\Local', 'LOGONSERVER': '\\\\XUEHAOWENG', 'MYSQL': 'C:\\Mysql\\mysql-8.0.13-winx64\\bin', 'NUMBER_OF_PROCESSORS': '8', 'ONEDRIVE': 'C:\\Users\\ŒÃ—ß∫¿\\OneDrive', 'OS': 'Windows_NT', 'PATH': 'C:\\Python\\Python36;C:\\Python27\\;C:\\Python27\\Scripts;C:\\Program Files (x86)\\Intel\\iCLS Client\\;C:\\Program Files\\Intel\\iCLS Client\\;C:\\Windows\\system32;C:\\Windows;C:\\Windows\\System32\\Wbem;C:\\Windows\\System32\\WindowsPowerShell\\v1.0\\;C:\\Program Files (x86)\\Intel\\Intel(R) Management Engine Components\\DAL;C:\\Program Files\\Intel\\Intel(R) Management Engine Components\\DAL;C:\\Program Files (x86)\\Intel\\Intel(R) Management Engine Components\\IPT;C:\\Program Files\\Intel\\Intel(R) Management Engine Components\\IPT;C:\\Program Files (x86)\\NVIDIA Corporation\\PhysX\\Common;C:\\Program Files\\Intel\\WiFi\\bin\\;C:\\Program Files\\Common Files\\Intel\\WirelessCommon\\;C:\\WINDOWS\\system32;C:\\WINDOWS;C:\\WINDOWS\\System32\\Wbem;C:\\WINDOWS\\System32\\WindowsPowerShell\\v1.0\\;C:\\WINDOWS\\System32\\OpenSSH\\;D:\\shortcut;C:\\Program Files\\Microsoft VS Code\\bin;C:\\Program Files\\;D:\\Git\\cmd;D:\\wxh\\tools\\node\\;C:\\Users\\ŒÃ—ß∫¿\\AppData\\Local\\Programs\\Python\\Python36\\Scripts\\;C:\\Users\\ŒÃ—ß∫¿\\AppData\\Local\\Programs\\Python\\Python36\\;C:\\Users\\ŒÃ—ß∫¿\\AppData\\Local\\Microsoft\\WindowsApps;D:\\wxh\\tools\\Microsoft VS Code\\bin;C:\\Users\\ŒÃ—ß∫¿\\AppData\\Local\\GitHubDesktop\\bin;D:\\shortcut;D:\\PyCharm 2019.1.3\\bin;;C:\\Mysql\\mysql-8.0.13-winx64\\bin;C:\\Program Files\\JetBrains\\PyCharm 2018.3.1\\bin;C:\\Python\\Python36\\Lib\\site-packages\\django;C:\\Python27\\Lib\\site-packages\\django;C:\\Python\\Python36\\;C:\\Python\\Python36\\Scripts;C:\\seleniumdirver\\chromedriver.exe;C:\\seleniumdirver\\phantomjs-2.1.1-windows\\bin\\phantomjs.exe;C:\\Users\\ŒÃ—ß∫¿\\AppData\\Roaming\\npm;C:\\Users\\ŒÃ—ß∫¿\\AppData\\Local\\Programs\\Python\\Python36\\lib\\site-packages\\numpy\\.libs;C:\\Users\\ŒÃ—ß∫¿\\AppData\\Local\\Programs\\Python\\Python36\\lib\\site-packages\\numpy\\.libs', 'PATHEXT': '.COM;.EXE;.BAT;.CMD;.VBS;.VBE;.JS;.JSE;.WSF;.WSH;.MSC', 'PROCESSOR_ARCHITECTURE': 'AMD64', 'PROCESSOR_IDENTIFIER': 'Intel64 Family 6 Model 142 Stepping 10, GenuineIntel', 'PROCESSOR_LEVEL': '6', 'PROCESSOR_REVISION': '8e0a', 'PROGRAMDATA': 'C:\\ProgramData', 'PROGRAMFILES': 'C:\\Program Files', 'PROGRAMFILES(X86)': 'C:\\Program Files (x86)', 'PROGRAMW6432': 'C:\\Program Files', 'PSMODULEPATH': 'C:\\Program Files\\WindowsPowerShell\\Modules;C:\\WINDOWS\\system32\\WindowsPowerShell\\v1.0\\Modules', 'PUBLIC': 'C:\\Users\\Public', 'PYCHARM': 'D:\\PyCharm 2019.1.3\\bin;', 'PYCHARM_DISPLAY_PORT': '4390', 'PYCHARM_HOSTED': '1', 'PYTHONIOENCODING': 'UTF-8', 'PYTHONPATH': 'D:\\wxh\\mysite;D:\\wxh\\mysite\\static;D:\\PyCharm 2019.1.3\\helpers\\pycharm_matplotlib_backend;D:\\PyCharm 2019.1.3\\helpers\\pycharm_display', 'PYTHONUNBUFFERED': '1', 'SESSIONNAME': 'Console', 'SYSTEMDRIVE': 'C:', 'SYSTEMROOT': 'C:\\WINDOWS', 'TEMP': 'C:\\Users\\ŒÃ—ß∫¿\\AppData\\Local\\Temp', 'TMP': 'C:\\Users\\ŒÃ—ß∫¿\\AppData\\Local\\Temp', 'USERDOMAIN': 'XUEHAOWENG', 'USERDOMAIN_ROAMINGPROFILE': 'XUEHAOWENG', 'USERNAME': 'ŒÃ—ß∫¿', 'USERPROFILE': 'C:\\Users\\ŒÃ—ß∫¿', 'WINDIR': 'C:\\WINDOWS', 'DJANGO_SETTINGS_MODULE': 'mysite.settings', 'RUN_MAIN': 'true', 'SERVER_NAME': 'xuehaoWeng', 'GATEWAY_INTERFACE': 'CGI/1.1', 'SERVER_PORT': '9000', 'REMOTE_HOST': '', 'CONTENT_LENGTH': '', 'SCRIPT_NAME': '', 'SERVER_PROTOCOL': 'HTTP/1.1', 'SERVER_SOFTWARE': 'WSGIServer/0.2', 'REQUEST_METHOD': 'GET', 'PATH_INFO': '/polls/get_man/', 'QUERY_STRING': '', 'REMOTE_ADDR': '127.0.0.1', 'CONTENT_TYPE': 'text/plain', 'HTTP_HOST': '127.0.0.1:9000', 'HTTP_CONNECTION': 'keep-alive', 'HTTP_CACHE_CONTROL': 'max-age=0', 'HTTP_UPGRADE_INSECURE_REQUESTS': '1', 'HTTP_USER_AGENT': 'Mozilla/5.0 (Windows NT 10.0; WOW64) AppleWebKit/537.36 (KHTML, like Gecko) Chrome/75.0.3770.100 Safari/537.36', 'HTTP_ACCEPT': 'text/html,application/xhtml+xml,application/xml;q=0.9,image/webp,image/apng,*/*;q=0.8,application/signed-exchange;v=b3', 'HTTP_ACCEPT_ENCODING': 'gzip, deflate, br', 'HTTP_ACCEPT_LANGUAGE': 'zh-CN,zh;q=0.9', 'HTTP_COOKIE': 'csrftoken=lniJGlOmYFoJl73WncIC04fLMHq7LeE8gJvyI068r4UoPIaqa9Hhjd6ZLxW03bgc; sessionid=8ukmepfgnk98ok5v8467337rgnhr9f90', 'wsgi.input': <django.core.handlers.wsgi.LimitedStream object at 0x00000258AF5B95C0>, 'wsgi.errors': <_io.TextIOWrapper name='<stderr>' mode='w' encoding='UTF-8'>, 'wsgi.version': (1, 0), 'wsgi.run_once': False, 'wsgi.url_scheme': 'http', 'wsgi.multithread': True, 'wsgi.multiprocess': False, 'wsgi.file_wrapper': <class 'wsgiref.util.FileWrapper'>}
ERROR 2019-07-18 11:22:57,859 log 228 Internal Server Error: /polls/get_man/
Traceback (most recent call last):
  File "C:\Users\ŒÃ—ß∫¿\AppData\Local\Programs\Python\Python36\lib\site-packages\django\core\handlers\exception.py", line 34, in inner
    response = get_response(request)
  File "C:\Users\ŒÃ—ß∫¿\AppData\Local\Programs\Python\Python36\lib\site-packages\django\core\handlers\base.py", line 126, in _get_response
    response = self.process_exception_by_middleware(e, request)
  File "C:\Users\ŒÃ—ß∫¿\AppData\Local\Programs\Python\Python36\lib\site-packages\django\core\handlers\base.py", line 124, in _get_response
    response = wrapped_callback(request, *callback_args, **callback_kwargs)
  File "C:\Users\ŒÃ—ß∫¿\AppData\Local\Programs\Python\Python36\lib\site-packages\django\views\generic\base.py", line 68, in view
    return self.dispatch(request, *args, **kwargs)
  File "C:\Users\ŒÃ—ß∫¿\AppData\Local\Programs\Python\Python36\lib\site-packages\django\views\generic\base.py", line 88, in dispatch
    return handler(request, *args, **kwargs)
  File "D:\wxh\mysite\apps\polls\views.py", line 95, in get
    logger.info(request.headers)
AttributeError: 'WSGIRequest' object has no attribute 'headers'
ERROR 2019-07-18 11:22:57,861 basehttp 154 "GET /polls/get_man/ HTTP/1.1" 500 78005
WARNING 2019-07-18 11:22:58,038 log 228 Not Found: /favicon.ico
WARNING 2019-07-18 11:22:58,039 basehttp 154 "GET /favicon.ico HTTP/1.1" 404 2187
ERROR 2019-07-18 11:23:53,984 log 228 Internal Server Error: /polls/get_man/
Traceback (most recent call last):
  File "C:\Users\ŒÃ—ß∫¿\AppData\Local\Programs\Python\Python36\lib\site-packages\django\core\handlers\exception.py", line 34, in inner
    response = get_response(request)
  File "C:\Users\ŒÃ—ß∫¿\AppData\Local\Programs\Python\Python36\lib\site-packages\django\core\handlers\base.py", line 126, in _get_response
    response = self.process_exception_by_middleware(e, request)
  File "C:\Users\ŒÃ—ß∫¿\AppData\Local\Programs\Python\Python36\lib\site-packages\django\core\handlers\base.py", line 124, in _get_response
    response = wrapped_callback(request, *callback_args, **callback_kwargs)
  File "C:\Users\ŒÃ—ß∫¿\AppData\Local\Programs\Python\Python36\lib\site-packages\django\views\generic\base.py", line 68, in view
    return self.dispatch(request, *args, **kwargs)
  File "C:\Users\ŒÃ—ß∫¿\AppData\Local\Programs\Python\Python36\lib\site-packages\django\views\generic\base.py", line 88, in dispatch
    return handler(request, *args, **kwargs)
  File "D:\wxh\mysite\apps\polls\views.py", line 101, in get
    values.sort()
AttributeError: 'dict_items' object has no attribute 'sort'
ERROR 2019-07-18 11:23:53,986 basehttp 154 "GET /polls/get_man/ HTTP/1.1" 500 83332
INFO 2019-07-18 11:25:43,534 basehttp 154 "GET /polls/get_man/ HTTP/1.1" 200 6607
WARNING 2019-07-19 10:46:28,649 log 228 Not Found: /
WARNING 2019-07-19 10:46:28,649 basehttp 154 "GET / HTTP/1.1" 404 2242
WARNING 2019-07-19 10:46:28,768 log 228 Not Found: /favicon.ico
WARNING 2019-07-19 10:46:28,769 basehttp 154 "GET /favicon.ico HTTP/1.1" 404 2293
INFO 2019-07-19 10:46:41,752 basehttp 154 "GET /books/search_form HTTP/1.1" 301 0
INFO 2019-07-19 10:46:41,762 basehttp 154 "GET /books/search_form/ HTTP/1.1" 200 183
INFO 2019-07-19 10:50:09,022 basehttp 154 "GET /books/search_form/ HTTP/1.1" 200 197
WARNING 2019-07-19 10:50:09,042 log 228 Not Found: /favicon.ico
WARNING 2019-07-19 10:50:09,042 basehttp 154 "GET /favicon.ico HTTP/1.1" 404 2293
ERROR 2019-07-19 10:50:10,661 log 228 Internal Server Error: /books/search/
Traceback (most recent call last):
  File "C:\Users\ŒÃ—ß∫¿\AppData\Local\Programs\Python\Python36\lib\site-packages\django\core\handlers\exception.py", line 34, in inner
    response = get_response(request)
  File "C:\Users\ŒÃ—ß∫¿\AppData\Local\Programs\Python\Python36\lib\site-packages\django\core\handlers\base.py", line 137, in _get_response
    "returned None instead." % (callback.__module__, view_name)
ValueError: The view apps.books.views.search didn't return an HttpResponse object. It returned None instead.
ERROR 2019-07-19 10:50:10,662 basehttp 154 "GET /books/search/?q= HTTP/1.1" 500 60464
ERROR 2019-07-19 10:50:17,920 log 228 Internal Server Error: /books/search/
Traceback (most recent call last):
  File "C:\Users\ŒÃ—ß∫¿\AppData\Local\Programs\Python\Python36\lib\site-packages\django\core\handlers\exception.py", line 34, in inner
    response = get_response(request)
  File "C:\Users\ŒÃ—ß∫¿\AppData\Local\Programs\Python\Python36\lib\site-packages\django\core\handlers\base.py", line 137, in _get_response
    "returned None instead." % (callback.__module__, view_name)
ValueError: The view apps.books.views.search didn't return an HttpResponse object. It returned None instead.
ERROR 2019-07-19 10:50:17,921 basehttp 154 "GET /books/search/?q=q HTTP/1.1" 500 60470
INFO 2019-07-19 10:50:41,262 basehttp 154 "GET /books/search_form/ HTTP/1.1" 200 197
INFO 2019-07-19 10:50:43,676 basehttp 154 "GET /books/search/?q=q HTTP/1.1" 200 21
INFO 2019-07-19 10:50:53,550 basehttp 154 "GET /books/search/?q= HTTP/1.1" 200 20
INFO 2019-07-19 10:52:06,239 basehttp 154 "GET /books/search_form/ HTTP/1.1" 200 197
INFO 2019-07-19 10:52:07,416 basehttp 154 "GET /books/search_form/ HTTP/1.1" 200 197
WARNING 2019-07-19 10:52:07,436 log 228 Not Found: /favicon.ico
WARNING 2019-07-19 10:52:07,436 basehttp 154 "GET /favicon.ico HTTP/1.1" 404 2293
INFO 2019-07-19 10:52:09,071 basehttp 154 "GET /books/search/?q= HTTP/1.1" 200 20
INFO 2019-07-19 10:53:00,334 basehttp 154 "GET /books/search/?q= HTTP/1.1" 200 20
WARNING 2019-07-19 10:53:00,351 log 228 Not Found: /favicon.ico
WARNING 2019-07-19 10:53:00,352 basehttp 154 "GET /favicon.ico HTTP/1.1" 404 2293
INFO 2019-07-19 10:53:05,051 basehttp 154 "GET /books/search/?q=%E5%9F%9F%E5%90%8D HTTP/1.1" 200 26
INFO 2019-07-19 10:53:08,615 basehttp 154 "GET /books/search/?q= HTTP/1.1" 200 20
INFO 2019-07-19 10:53:37,036 basehttp 154 "GET /books/search_form/ HTTP/1.1" 200 197
WARNING 2019-07-19 10:53:37,081 log 228 Not Found: /favicon.ico
WARNING 2019-07-19 10:53:37,082 basehttp 154 "GET /favicon.ico HTTP/1.1" 404 2293
INFO 2019-07-19 10:53:38,631 basehttp 154 "GET /books/search/?q= HTTP/1.1" 200 20
INFO 2019-07-19 10:53:43,414 basehttp 154 "GET /books/search/?q=. HTTP/1.1" 200 21
INFO 2019-07-19 10:57:17,391 basehttp 154 "GET /books/search_form/ HTTP/1.1" 200 197
WARNING 2019-07-19 10:57:17,410 log 228 Not Found: /favicon.ico
WARNING 2019-07-19 10:57:17,410 basehttp 154 "GET /favicon.ico HTTP/1.1" 404 2293
INFO 2019-07-19 10:57:20,183 basehttp 154 "GET /books/search/?q=%E5%9F%9F%E5%90%8D HTTP/1.1" 200 97
INFO 2019-07-19 11:00:48,909 basehttp 154 "GET /books/search/?q=%E5%9F%9F%E5%90%8D HTTP/1.1" 200 114
INFO 2019-07-19 11:06:35,414 basehttp 154 "GET /books/search/?q= HTTP/1.1" 200 28
INFO 2019-07-19 11:06:39,352 basehttp 154 "GET /books/search/?q=weng HTTP/1.1" 200 95
INFO 2019-07-19 11:07:43,257 basehttp 154 "GET /books/search_form/ HTTP/1.1" 200 197
INFO 2019-07-19 11:07:45,540 basehttp 154 "GET /books/search/?q=%E5%9F%9F%E5%90%8D HTTP/1.1" 200 142
INFO 2019-07-19 11:07:52,953 basehttp 154 "GET /books/search/?q=%E5%9F%9F HTTP/1.1" 200 139
INFO 2019-07-19 11:07:57,841 basehttp 154 "GET /books/search/?q=weng HTTP/1.1" 200 75
INFO 2019-07-19 11:08:30,320 basehttp 154 "GET /books/search/?q=weng HTTP/1.1" 200 75
INFO 2019-07-19 11:08:31,347 basehttp 154 "GET /books/search/?q=weng HTTP/1.1" 200 75
INFO 2019-07-19 11:08:33,153 basehttp 154 "GET /books/search/?q=weng HTTP/1.1" 200 75
WARNING 2019-07-19 11:08:33,174 log 228 Not Found: /favicon.ico
WARNING 2019-07-19 11:08:33,174 basehttp 154 "GET /favicon.ico HTTP/1.1" 404 2293
INFO 2019-07-19 11:08:38,262 basehttp 154 "GET /books/search_form/ HTTP/1.1" 200 197
WARNING 2019-07-19 11:08:38,280 log 228 Not Found: /favicon.ico
WARNING 2019-07-19 11:08:38,280 basehttp 154 "GET /favicon.ico HTTP/1.1" 404 2293
INFO 2019-07-19 11:08:42,690 basehttp 154 "GET /books/search/?q=%E5%9F%9F%E5%90%8D HTTP/1.1" 200 196
INFO 2019-07-19 11:09:19,898 basehttp 154 "GET /books/search/?q= HTTP/1.1" 200 28
INFO 2019-07-19 11:15:23,106 basehttp 154 "GET /books/search/?q= HTTP/1.1" 200 257
INFO 2019-07-19 11:16:43,915 basehttp 154 "GET /books/search_form/ HTTP/1.1" 200 198
INFO 2019-07-19 11:16:47,533 basehttp 154 "GET /books/search/?q=python%E7%9A%84app%E5%BC%80%E5%8F%91 HTTP/1.1" 200 89
INFO 2019-07-19 11:16:53,369 basehttp 154 "GET /books/search/?q=%E5%9F%9F%E5%90%8D HTTP/1.1" 200 142
INFO 2019-07-19 11:16:56,827 basehttp 154 "GET /books/search/?q= HTTP/1.1" 200 257
INFO 2019-07-19 11:21:26,078 basehttp 154 "GET /books/search_form/ HTTP/1.1" 200 198
WARNING 2019-07-19 16:26:40,071 log 228 Not Found: /
WARNING 2019-07-19 16:26:40,072 basehttp 154 "GET / HTTP/1.1" 404 2349
WARNING 2019-07-19 16:26:40,202 log 228 Not Found: /favicon.ico
WARNING 2019-07-19 16:26:40,203 basehttp 154 "GET /favicon.ico HTTP/1.1" 404 2400
WARNING 2019-07-19 16:26:46,479 log 228 Not Found: /books/search_form/
WARNING 2019-07-19 16:26:46,480 basehttp 154 "GET /books/search_form/ HTTP/1.1" 404 2499
INFO 2019-07-19 16:26:50,574 basehttp 154 "GET /books/search HTTP/1.1" 301 0
ERROR 2019-07-19 16:26:50,618 log 228 Internal Server Error: /books/search/
Traceback (most recent call last):
  File "C:\Users\ŒÃ—ß∫¿\AppData\Local\Programs\Python\Python36\lib\site-packages\django\core\handlers\exception.py", line 34, in inner
    response = get_response(request)
  File "C:\Users\ŒÃ—ß∫¿\AppData\Local\Programs\Python\Python36\lib\site-packages\django\core\handlers\base.py", line 126, in _get_response
    response = self.process_exception_by_middleware(e, request)
  File "C:\Users\ŒÃ—ß∫¿\AppData\Local\Programs\Python\Python36\lib\site-packages\django\core\handlers\base.py", line 124, in _get_response
    response = wrapped_callback(request, *callback_args, **callback_kwargs)
  File "C:\Users\ŒÃ—ß∫¿\AppData\Local\Programs\Python\Python36\lib\site-packages\django\views\generic\base.py", line 68, in view
    return self.dispatch(request, *args, **kwargs)
  File "C:\Users\ŒÃ—ß∫¿\AppData\Local\Programs\Python\Python36\lib\site-packages\django\views\generic\base.py", line 88, in dispatch
    return handler(request, *args, **kwargs)
  File "C:\Users\ŒÃ—ß∫¿\AppData\Local\Programs\Python\Python36\lib\site-packages\haystack\generic_views.py", line 126, in get
    return self.form_valid(form)
  File "C:\Users\ŒÃ—ß∫¿\AppData\Local\Programs\Python\Python36\lib\site-packages\haystack\generic_views.py", line 83, in form_valid
    'object_list': self.queryset
  File "D:\wxh\mysite\apps\books\views.py", line 33, in get_context_data
    form_data = mySearchView.get_form_kwargs()['q']
KeyError: 'q'
ERROR 2019-07-19 16:26:50,619 basehttp 154 "GET /books/search/ HTTP/1.1" 500 87146
ERROR 2019-07-19 16:27:04,833 log 228 Internal Server Error: /books/search/
Traceback (most recent call last):
  File "C:\Users\ŒÃ—ß∫¿\AppData\Local\Programs\Python\Python36\lib\site-packages\django\core\handlers\exception.py", line 34, in inner
    response = get_response(request)
  File "C:\Users\ŒÃ—ß∫¿\AppData\Local\Programs\Python\Python36\lib\site-packages\django\core\handlers\base.py", line 156, in _get_response
    response = self.process_exception_by_middleware(e, request)
  File "C:\Users\ŒÃ—ß∫¿\AppData\Local\Programs\Python\Python36\lib\site-packages\django\core\handlers\base.py", line 154, in _get_response
    response = response.render()
  File "C:\Users\ŒÃ—ß∫¿\AppData\Local\Programs\Python\Python36\lib\site-packages\django\template\response.py", line 106, in render
    self.content = self.rendered_content
  File "C:\Users\ŒÃ—ß∫¿\AppData\Local\Programs\Python\Python36\lib\site-packages\django\template\response.py", line 83, in rendered_content
    content = template.render(context, self._request)
  File "C:\Users\ŒÃ—ß∫¿\AppData\Local\Programs\Python\Python36\lib\site-packages\django\template\backends\django.py", line 61, in render
    return self.template.render(context)
  File "C:\Users\ŒÃ—ß∫¿\AppData\Local\Programs\Python\Python36\lib\site-packages\django\template\base.py", line 171, in render
    return self._render(context)
  File "C:\Users\ŒÃ—ß∫¿\AppData\Local\Programs\Python\Python36\lib\site-packages\django\template\base.py", line 163, in _render
    return self.nodelist.render(context)
  File "C:\Users\ŒÃ—ß∫¿\AppData\Local\Programs\Python\Python36\lib\site-packages\django\template\base.py", line 937, in render
    bit = node.render_annotated(context)
  File "C:\Users\ŒÃ—ß∫¿\AppData\Local\Programs\Python\Python36\lib\site-packages\django\template\base.py", line 904, in render_annotated
    return self.render(context)
  File "C:\Users\ŒÃ—ß∫¿\AppData\Local\Programs\Python\Python36\lib\site-packages\django\template\defaulttags.py", line 442, in render
    url = reverse(view_name, args=args, kwargs=kwargs, current_app=current_app)
  File "C:\Users\ŒÃ—ß∫¿\AppData\Local\Programs\Python\Python36\lib\site-packages\django\urls\base.py", line 90, in reverse
    return iri_to_uri(resolver._reverse_with_prefix(view, prefix, *args, **kwargs))
  File "C:\Users\ŒÃ—ß∫¿\AppData\Local\Programs\Python\Python36\lib\site-packages\django\urls\resolvers.py", line 622, in _reverse_with_prefix
    raise NoReverseMatch(msg)
django.urls.exceptions.NoReverseMatch: Reverse for 'search' not found. 'search' is not a valid view function or pattern name.
ERROR 2019-07-19 16:27:04,835 basehttp 154 "GET /books/search/ HTTP/1.1" 500 117349
INFO 2019-07-19 16:28:08,861 basehttp 154 "GET /books/search/ HTTP/1.1" 200 6
ERROR 2019-07-19 16:28:37,740 log 228 Internal Server Error: /books/search/
Traceback (most recent call last):
  File "C:\Users\ŒÃ—ß∫¿\AppData\Local\Programs\Python\Python36\lib\site-packages\django\core\handlers\exception.py", line 34, in inner
    response = get_response(request)
  File "C:\Users\ŒÃ—ß∫¿\AppData\Local\Programs\Python\Python36\lib\site-packages\django\core\handlers\base.py", line 126, in _get_response
    response = self.process_exception_by_middleware(e, request)
  File "C:\Users\ŒÃ—ß∫¿\AppData\Local\Programs\Python\Python36\lib\site-packages\django\core\handlers\base.py", line 124, in _get_response
    response = wrapped_callback(request, *callback_args, **callback_kwargs)
  File "C:\Users\ŒÃ—ß∫¿\AppData\Local\Programs\Python\Python36\lib\site-packages\django\views\generic\base.py", line 68, in view
    return self.dispatch(request, *args, **kwargs)
  File "C:\Users\ŒÃ—ß∫¿\AppData\Local\Programs\Python\Python36\lib\site-packages\django\views\generic\base.py", line 88, in dispatch
    return handler(request, *args, **kwargs)
  File "D:\wxh\mysite\apps\books\views.py", line 34, in get
    return render_to_response('search_form.html', {'error': True})
  File "C:\Users\ŒÃ—ß∫¿\AppData\Local\Programs\Python\Python36\lib\site-packages\django\shortcuts.py", line 27, in render_to_response
    content = loader.render_to_string(template_name, context, using=using)
  File "C:\Users\ŒÃ—ß∫¿\AppData\Local\Programs\Python\Python36\lib\site-packages\django\template\loader.py", line 62, in render_to_string
    return template.render(context, request)
  File "C:\Users\ŒÃ—ß∫¿\AppData\Local\Programs\Python\Python36\lib\site-packages\django\template\backends\django.py", line 61, in render
    return self.template.render(context)
  File "C:\Users\ŒÃ—ß∫¿\AppData\Local\Programs\Python\Python36\lib\site-packages\django\template\base.py", line 171, in render
    return self._render(context)
  File "C:\Users\ŒÃ—ß∫¿\AppData\Local\Programs\Python\Python36\lib\site-packages\django\template\base.py", line 163, in _render
    return self.nodelist.render(context)
  File "C:\Users\ŒÃ—ß∫¿\AppData\Local\Programs\Python\Python36\lib\site-packages\django\template\base.py", line 937, in render
    bit = node.render_annotated(context)
  File "C:\Users\ŒÃ—ß∫¿\AppData\Local\Programs\Python\Python36\lib\site-packages\django\template\base.py", line 904, in render_annotated
    return self.render(context)
  File "C:\Users\ŒÃ—ß∫¿\AppData\Local\Programs\Python\Python36\lib\site-packages\django\template\defaulttags.py", line 442, in render
    url = reverse(view_name, args=args, kwargs=kwargs, current_app=current_app)
  File "C:\Users\ŒÃ—ß∫¿\AppData\Local\Programs\Python\Python36\lib\site-packages\django\urls\base.py", line 90, in reverse
    return iri_to_uri(resolver._reverse_with_prefix(view, prefix, *args, **kwargs))
  File "C:\Users\ŒÃ—ß∫¿\AppData\Local\Programs\Python\Python36\lib\site-packages\django\urls\resolvers.py", line 622, in _reverse_with_prefix
    raise NoReverseMatch(msg)
django.urls.exceptions.NoReverseMatch: Reverse for 'search' not found. 'search' is not a valid view function or pattern name.
ERROR 2019-07-19 16:28:37,743 basehttp 154 "GET /books/search/ HTTP/1.1" 500 127461
ERROR 2019-07-19 16:29:47,346 log 228 Internal Server Error: /books/search/
Traceback (most recent call last):
  File "C:\Users\ŒÃ—ß∫¿\AppData\Local\Programs\Python\Python36\lib\site-packages\django\core\handlers\exception.py", line 34, in inner
    response = get_response(request)
  File "C:\Users\ŒÃ—ß∫¿\AppData\Local\Programs\Python\Python36\lib\site-packages\django\core\handlers\base.py", line 126, in _get_response
    response = self.process_exception_by_middleware(e, request)
  File "C:\Users\ŒÃ—ß∫¿\AppData\Local\Programs\Python\Python36\lib\site-packages\django\core\handlers\base.py", line 124, in _get_response
    response = wrapped_callback(request, *callback_args, **callback_kwargs)
  File "C:\Users\ŒÃ—ß∫¿\AppData\Local\Programs\Python\Python36\lib\site-packages\django\views\generic\base.py", line 68, in view
    return self.dispatch(request, *args, **kwargs)
  File "C:\Users\ŒÃ—ß∫¿\AppData\Local\Programs\Python\Python36\lib\site-packages\django\views\generic\base.py", line 88, in dispatch
    return handler(request, *args, **kwargs)
  File "D:\wxh\mysite\apps\books\views.py", line 34, in get
    return render_to_response('search_form.html', {'error': True})
  File "C:\Users\ŒÃ—ß∫¿\AppData\Local\Programs\Python\Python36\lib\site-packages\django\shortcuts.py", line 27, in render_to_response
    content = loader.render_to_string(template_name, context, using=using)
  File "C:\Users\ŒÃ—ß∫¿\AppData\Local\Programs\Python\Python36\lib\site-packages\django\template\loader.py", line 62, in render_to_string
    return template.render(context, request)
  File "C:\Users\ŒÃ—ß∫¿\AppData\Local\Programs\Python\Python36\lib\site-packages\django\template\backends\django.py", line 61, in render
    return self.template.render(context)
  File "C:\Users\ŒÃ—ß∫¿\AppData\Local\Programs\Python\Python36\lib\site-packages\django\template\base.py", line 171, in render
    return self._render(context)
  File "C:\Users\ŒÃ—ß∫¿\AppData\Local\Programs\Python\Python36\lib\site-packages\django\template\base.py", line 163, in _render
    return self.nodelist.render(context)
  File "C:\Users\ŒÃ—ß∫¿\AppData\Local\Programs\Python\Python36\lib\site-packages\django\template\base.py", line 937, in render
    bit = node.render_annotated(context)
  File "C:\Users\ŒÃ—ß∫¿\AppData\Local\Programs\Python\Python36\lib\site-packages\django\template\base.py", line 904, in render_annotated
    return self.render(context)
  File "C:\Users\ŒÃ—ß∫¿\AppData\Local\Programs\Python\Python36\lib\site-packages\django\template\defaulttags.py", line 442, in render
    url = reverse(view_name, args=args, kwargs=kwargs, current_app=current_app)
  File "C:\Users\ŒÃ—ß∫¿\AppData\Local\Programs\Python\Python36\lib\site-packages\django\urls\base.py", line 90, in reverse
    return iri_to_uri(resolver._reverse_with_prefix(view, prefix, *args, **kwargs))
  File "C:\Users\ŒÃ—ß∫¿\AppData\Local\Programs\Python\Python36\lib\site-packages\django\urls\resolvers.py", line 622, in _reverse_with_prefix
    raise NoReverseMatch(msg)
django.urls.exceptions.NoReverseMatch: Reverse for '' not found. '' is not a valid view function or pattern name.
ERROR 2019-07-19 16:29:47,347 basehttp 154 "GET /books/search/ HTTP/1.1" 500 127315
ERROR 2019-07-19 16:29:54,974 log 228 Internal Server Error: /books/search/
Traceback (most recent call last):
  File "C:\Users\ŒÃ—ß∫¿\AppData\Local\Programs\Python\Python36\lib\site-packages\django\core\handlers\exception.py", line 34, in inner
    response = get_response(request)
  File "C:\Users\ŒÃ—ß∫¿\AppData\Local\Programs\Python\Python36\lib\site-packages\django\core\handlers\base.py", line 126, in _get_response
    response = self.process_exception_by_middleware(e, request)
  File "C:\Users\ŒÃ—ß∫¿\AppData\Local\Programs\Python\Python36\lib\site-packages\django\core\handlers\base.py", line 124, in _get_response
    response = wrapped_callback(request, *callback_args, **callback_kwargs)
  File "C:\Users\ŒÃ—ß∫¿\AppData\Local\Programs\Python\Python36\lib\site-packages\django\views\generic\base.py", line 68, in view
    return self.dispatch(request, *args, **kwargs)
  File "C:\Users\ŒÃ—ß∫¿\AppData\Local\Programs\Python\Python36\lib\site-packages\django\views\generic\base.py", line 88, in dispatch
    return handler(request, *args, **kwargs)
  File "D:\wxh\mysite\apps\books\views.py", line 34, in get
    return render_to_response('search_form.html', {'error': True})
  File "C:\Users\ŒÃ—ß∫¿\AppData\Local\Programs\Python\Python36\lib\site-packages\django\shortcuts.py", line 27, in render_to_response
    content = loader.render_to_string(template_name, context, using=using)
  File "C:\Users\ŒÃ—ß∫¿\AppData\Local\Programs\Python\Python36\lib\site-packages\django\template\loader.py", line 62, in render_to_string
    return template.render(context, request)
  File "C:\Users\ŒÃ—ß∫¿\AppData\Local\Programs\Python\Python36\lib\site-packages\django\template\backends\django.py", line 61, in render
    return self.template.render(context)
  File "C:\Users\ŒÃ—ß∫¿\AppData\Local\Programs\Python\Python36\lib\site-packages\django\template\base.py", line 171, in render
    return self._render(context)
  File "C:\Users\ŒÃ—ß∫¿\AppData\Local\Programs\Python\Python36\lib\site-packages\django\template\base.py", line 163, in _render
    return self.nodelist.render(context)
  File "C:\Users\ŒÃ—ß∫¿\AppData\Local\Programs\Python\Python36\lib\site-packages\django\template\base.py", line 937, in render
    bit = node.render_annotated(context)
  File "C:\Users\ŒÃ—ß∫¿\AppData\Local\Programs\Python\Python36\lib\site-packages\django\template\base.py", line 904, in render_annotated
    return self.render(context)
  File "C:\Users\ŒÃ—ß∫¿\AppData\Local\Programs\Python\Python36\lib\site-packages\django\template\defaulttags.py", line 442, in render
    url = reverse(view_name, args=args, kwargs=kwargs, current_app=current_app)
  File "C:\Users\ŒÃ—ß∫¿\AppData\Local\Programs\Python\Python36\lib\site-packages\django\urls\base.py", line 90, in reverse
    return iri_to_uri(resolver._reverse_with_prefix(view, prefix, *args, **kwargs))
  File "C:\Users\ŒÃ—ß∫¿\AppData\Local\Programs\Python\Python36\lib\site-packages\django\urls\resolvers.py", line 622, in _reverse_with_prefix
    raise NoReverseMatch(msg)
django.urls.exceptions.NoReverseMatch: Reverse for 'search' not found. 'search' is not a valid view function or pattern name.
ERROR 2019-07-19 16:29:54,976 basehttp 154 "GET /books/search/ HTTP/1.1" 500 127461
ERROR 2019-07-19 16:30:01,203 log 228 Internal Server Error: /books/search/
Traceback (most recent call last):
  File "C:\Users\ŒÃ—ß∫¿\AppData\Local\Programs\Python\Python36\lib\site-packages\django\core\handlers\exception.py", line 34, in inner
    response = get_response(request)
  File "C:\Users\ŒÃ—ß∫¿\AppData\Local\Programs\Python\Python36\lib\site-packages\django\core\handlers\base.py", line 126, in _get_response
    response = self.process_exception_by_middleware(e, request)
  File "C:\Users\ŒÃ—ß∫¿\AppData\Local\Programs\Python\Python36\lib\site-packages\django\core\handlers\base.py", line 124, in _get_response
    response = wrapped_callback(request, *callback_args, **callback_kwargs)
TypeError: __init__() takes 1 positional argument but 2 were given
ERROR 2019-07-19 16:30:01,205 basehttp 154 "GET /books/search/ HTTP/1.1" 500 65937
WARNING 2019-07-19 16:30:01,275 log 228 Not Found: /favicon.ico
WARNING 2019-07-19 16:30:01,276 basehttp 154 "GET /favicon.ico HTTP/1.1" 404 2400
INFO 2019-07-19 16:30:24,420 basehttp 154 "GET /books/search/ HTTP/1.1" 200 257
ERROR 2019-07-19 16:30:26,852 log 228 Internal Server Error: /books/search/
Traceback (most recent call last):
  File "C:\Users\ŒÃ—ß∫¿\AppData\Local\Programs\Python\Python36\lib\site-packages\django\core\handlers\exception.py", line 34, in inner
    response = get_response(request)
  File "C:\Users\ŒÃ—ß∫¿\AppData\Local\Programs\Python\Python36\lib\site-packages\django\core\handlers\base.py", line 126, in _get_response
    response = self.process_exception_by_middleware(e, request)
  File "C:\Users\ŒÃ—ß∫¿\AppData\Local\Programs\Python\Python36\lib\site-packages\django\core\handlers\base.py", line 124, in _get_response
    response = wrapped_callback(request, *callback_args, **callback_kwargs)
  File "C:\Users\ŒÃ—ß∫¿\AppData\Local\Programs\Python\Python36\lib\site-packages\django\views\generic\base.py", line 68, in view
    return self.dispatch(request, *args, **kwargs)
  File "C:\Users\ŒÃ—ß∫¿\AppData\Local\Programs\Python\Python36\lib\site-packages\django\views\generic\base.py", line 88, in dispatch
    return handler(request, *args, **kwargs)
  File "D:\wxh\mysite\apps\books\views.py", line 32, in get
    {'books': books, 'query': q})
  File "C:\Users\ŒÃ—ß∫¿\AppData\Local\Programs\Python\Python36\lib\site-packages\django\shortcuts.py", line 27, in render_to_response
    content = loader.render_to_string(template_name, context, using=using)
  File "C:\Users\ŒÃ—ß∫¿\AppData\Local\Programs\Python\Python36\lib\site-packages\django\template\loader.py", line 62, in render_to_string
    return template.render(context, request)
  File "C:\Users\ŒÃ—ß∫¿\AppData\Local\Programs\Python\Python36\lib\site-packages\django\template\backends\django.py", line 61, in render
    return self.template.render(context)
  File "C:\Users\ŒÃ—ß∫¿\AppData\Local\Programs\Python\Python36\lib\site-packages\django\template\base.py", line 171, in render
    return self._render(context)
  File "C:\Users\ŒÃ—ß∫¿\AppData\Local\Programs\Python\Python36\lib\site-packages\django\template\base.py", line 163, in _render
    return self.nodelist.render(context)
  File "C:\Users\ŒÃ—ß∫¿\AppData\Local\Programs\Python\Python36\lib\site-packages\django\template\base.py", line 937, in render
    bit = node.render_annotated(context)
  File "C:\Users\ŒÃ—ß∫¿\AppData\Local\Programs\Python\Python36\lib\site-packages\django\template\base.py", line 904, in render_annotated
    return self.render(context)
  File "C:\Users\ŒÃ—ß∫¿\AppData\Local\Programs\Python\Python36\lib\site-packages\django\template\defaulttags.py", line 442, in render
    url = reverse(view_name, args=args, kwargs=kwargs, current_app=current_app)
  File "C:\Users\ŒÃ—ß∫¿\AppData\Local\Programs\Python\Python36\lib\site-packages\django\urls\base.py", line 90, in reverse
    return iri_to_uri(resolver._reverse_with_prefix(view, prefix, *args, **kwargs))
  File "C:\Users\ŒÃ—ß∫¿\AppData\Local\Programs\Python\Python36\lib\site-packages\django\urls\resolvers.py", line 622, in _reverse_with_prefix
    raise NoReverseMatch(msg)
django.urls.exceptions.NoReverseMatch: Reverse for 'search_form' not found. 'search_form' is not a valid view function or pattern name.
ERROR 2019-07-19 16:30:26,855 basehttp 154 "GET /books/search/?q=%E5%9F%9F%E5%90%8D HTTP/1.1" 500 129617
ERROR 2019-07-19 16:30:32,501 log 228 Internal Server Error: /books/search/
Traceback (most recent call last):
  File "C:\Users\ŒÃ—ß∫¿\AppData\Local\Programs\Python\Python36\lib\site-packages\django\core\handlers\exception.py", line 34, in inner
    response = get_response(request)
  File "C:\Users\ŒÃ—ß∫¿\AppData\Local\Programs\Python\Python36\lib\site-packages\django\core\handlers\base.py", line 126, in _get_response
    response = self.process_exception_by_middleware(e, request)
  File "C:\Users\ŒÃ—ß∫¿\AppData\Local\Programs\Python\Python36\lib\site-packages\django\core\handlers\base.py", line 124, in _get_response
    response = wrapped_callback(request, *callback_args, **callback_kwargs)
  File "C:\Users\ŒÃ—ß∫¿\AppData\Local\Programs\Python\Python36\lib\site-packages\django\views\generic\base.py", line 68, in view
    return self.dispatch(request, *args, **kwargs)
  File "C:\Users\ŒÃ—ß∫¿\AppData\Local\Programs\Python\Python36\lib\site-packages\django\views\generic\base.py", line 88, in dispatch
    return handler(request, *args, **kwargs)
  File "D:\wxh\mysite\apps\books\views.py", line 32, in get
    {'books': books, 'query': q})
  File "C:\Users\ŒÃ—ß∫¿\AppData\Local\Programs\Python\Python36\lib\site-packages\django\shortcuts.py", line 27, in render_to_response
    content = loader.render_to_string(template_name, context, using=using)
  File "C:\Users\ŒÃ—ß∫¿\AppData\Local\Programs\Python\Python36\lib\site-packages\django\template\loader.py", line 62, in render_to_string
    return template.render(context, request)
  File "C:\Users\ŒÃ—ß∫¿\AppData\Local\Programs\Python\Python36\lib\site-packages\django\template\backends\django.py", line 61, in render
    return self.template.render(context)
  File "C:\Users\ŒÃ—ß∫¿\AppData\Local\Programs\Python\Python36\lib\site-packages\django\template\base.py", line 171, in render
    return self._render(context)
  File "C:\Users\ŒÃ—ß∫¿\AppData\Local\Programs\Python\Python36\lib\site-packages\django\template\base.py", line 163, in _render
    return self.nodelist.render(context)
  File "C:\Users\ŒÃ—ß∫¿\AppData\Local\Programs\Python\Python36\lib\site-packages\django\template\base.py", line 937, in render
    bit = node.render_annotated(context)
  File "C:\Users\ŒÃ—ß∫¿\AppData\Local\Programs\Python\Python36\lib\site-packages\django\template\base.py", line 904, in render_annotated
    return self.render(context)
  File "C:\Users\ŒÃ—ß∫¿\AppData\Local\Programs\Python\Python36\lib\site-packages\django\template\defaulttags.py", line 442, in render
    url = reverse(view_name, args=args, kwargs=kwargs, current_app=current_app)
  File "C:\Users\ŒÃ—ß∫¿\AppData\Local\Programs\Python\Python36\lib\site-packages\django\urls\base.py", line 90, in reverse
    return iri_to_uri(resolver._reverse_with_prefix(view, prefix, *args, **kwargs))
  File "C:\Users\ŒÃ—ß∫¿\AppData\Local\Programs\Python\Python36\lib\site-packages\django\urls\resolvers.py", line 622, in _reverse_with_prefix
    raise NoReverseMatch(msg)
django.urls.exceptions.NoReverseMatch: Reverse for 'search_form' not found. 'search_form' is not a valid view function or pattern name.
ERROR 2019-07-19 16:30:32,503 basehttp 154 "GET /books/search/?q=%E5%9F%9F%E5%90%8D HTTP/1.1" 500 129617
INFO 2019-07-19 16:31:31,491 basehttp 154 "GET /books/search/ HTTP/1.1" 200 257
INFO 2019-07-19 16:31:33,811 basehttp 154 "GET /books/search/?q=%E5%9F%9F%E5%90%8D HTTP/1.1" 200 314
INFO 2019-07-19 16:31:36,566 basehttp 154 "GET /books/search_form/?q=weng HTTP/1.1" 200 198
INFO 2019-07-19 16:31:56,343 basehttp 154 "GET /books/search/?q=%E5%9F%9F%E5%90%8D HTTP/1.1" 200 77
INFO 2019-07-19 16:32:05,860 basehttp 154 "GET /books/search/?q=%E4%B9%A6%E7%B1%8D HTTP/1.1" 200 77
INFO 2019-07-19 16:32:37,272 basehttp 154 "GET /books/search/?q=%E4%B9%A6%E7%B1%8D HTTP/1.1" 200 142
INFO 2019-07-19 16:32:40,681 basehttp 154 "GET /books/search/?q=%E4%B9%A6%E7%B1%8D HTTP/1.1" 200 142
INFO 2019-07-19 16:33:47,537 basehttp 154 "GET /books/search/?q=. HTTP/1.1" 200 72
INFO 2019-07-22 16:19:30,835 autoreload 576 Watching for file changes with StatReloader
INFO 2019-07-22 16:19:57,319 autoreload 576 Watching for file changes with StatReloader
INFO 2019-07-22 16:20:44,376 autoreload 576 Watching for file changes with StatReloader
INFO 2019-07-22 16:21:21,120 autoreload 203 D:\wxh\mysite\mysite\settings.py changed, reloading.
INFO 2019-07-22 16:21:21,782 autoreload 576 Watching for file changes with StatReloader
INFO 2019-07-22 16:21:27,004 autoreload 576 Watching for file changes with StatReloader
INFO 2019-07-22 16:22:27,577 autoreload 576 Watching for file changes with StatReloader
INFO 2019-07-22 16:22:43,315 autoreload 576 Watching for file changes with StatReloader
WARNING 2019-07-22 16:22:49,194 log 228 Not Found: /
WARNING 2019-07-22 16:22:49,195 basehttp 154 "GET / HTTP/1.1" 404 2242
WARNING 2019-07-22 16:22:49,327 log 228 Not Found: /favicon.ico
WARNING 2019-07-22 16:22:49,327 basehttp 154 "GET /favicon.ico HTTP/1.1" 404 2293
INFO 2019-07-22 16:23:03,618 basehttp 154 "GET /books/search/ HTTP/1.1" 200 257
INFO 2019-07-22 16:23:11,236 basehttp 154 "GET /books/search/?q=%E5%9F%9F%E5%90%8D HTTP/1.1" 200 77
INFO 2019-07-22 16:23:16,060 basehttp 154 "GET /books/search/?q=weng HTTP/1.1" 200 75
INFO 2019-07-22 16:23:34,210 autoreload 203 D:\wxh\mysite\mysite\settings.py changed, reloading.
INFO 2019-07-22 16:23:34,820 autoreload 576 Watching for file changes with StatReloader
INFO 2019-07-22 16:26:37,608 autoreload 576 Watching for file changes with StatReloader
INFO 2019-07-22 18:10:41,404 autoreload 576 Watching for file changes with StatReloader
INFO 2019-07-22 18:10:51,215 autoreload 576 Watching for file changes with StatReloader
INFO 2019-07-22 18:12:24,903 autoreload 576 Watching for file changes with StatReloader
INFO 2019-07-22 18:12:46,804 autoreload 576 Watching for file changes with StatReloader
INFO 2019-07-22 18:13:17,252 autoreload 576 Watching for file changes with StatReloader
INFO 2019-07-22 18:13:54,664 autoreload 576 Watching for file changes with StatReloader
INFO 2019-07-22 18:14:00,167 autoreload 576 Watching for file changes with StatReloader
INFO 2019-07-22 18:14:30,767 autoreload 576 Watching for file changes with StatReloader
INFO 2019-07-22 18:15:31,573 autoreload 576 Watching for file changes with StatReloader
INFO 2019-07-22 18:15:42,524 autoreload 576 Watching for file changes with StatReloader
INFO 2019-07-22 18:17:10,132 autoreload 576 Watching for file changes with StatReloader
INFO 2019-07-22 18:18:18,310 autoreload 576 Watching for file changes with StatReloader
INFO 2019-07-22 18:19:39,495 autoreload 576 Watching for file changes with StatReloader
INFO 2019-07-22 21:19:51,608 autoreload 576 Watching for file changes with StatReloader
INFO 2019-07-22 21:22:00,316 autoreload 576 Watching for file changes with StatReloader
INFO 2019-07-22 21:24:28,042 autoreload 576 Watching for file changes with StatReloader
INFO 2019-07-22 21:25:07,899 autoreload 576 Watching for file changes with StatReloader
INFO 2019-07-22 21:25:28,275 autoreload 576 Watching for file changes with StatReloader
INFO 2019-07-22 21:28:25,713 autoreload 203 C:\Anaconda\envs\envtest\Lib\site-packages\django\conf\locale\__init__.py changed, reloading.
WARNING 2019-07-22 21:49:19,373 log 228 Not Found: /
WARNING 2019-07-22 21:49:19,373 basehttp 154 "GET / HTTP/1.1" 404 2242
WARNING 2019-07-22 21:49:19,501 log 228 Not Found: /favicon.ico
WARNING 2019-07-22 21:49:19,501 basehttp 154 "GET /favicon.ico HTTP/1.1" 404 2293
INFO 2019-07-22 21:49:31,336 basehttp 154 "GET /books/search/ HTTP/1.1" 200 257
INFO 2019-07-24 10:57:29,085 autoreload 576 Watching for file changes with StatReloader
INFO 2019-07-24 10:58:07,764 autoreload 576 Watching for file changes with StatReloader
INFO 2019-07-24 11:00:48,213 autoreload 203 C:\Anaconda\envs\envtest\Lib\site-packages\django\db\backends\mysql\base.py changed, reloading.
INFO 2019-07-24 11:00:49,169 autoreload 576 Watching for file changes with StatReloader
INFO 2019-07-24 11:01:05,936 autoreload 576 Watching for file changes with StatReloader
INFO 2019-07-24 11:03:37,160 autoreload 576 Watching for file changes with StatReloader
INFO 2019-07-24 11:04:47,477 autoreload 203 C:\Anaconda\envs\envtest\Lib\site-packages\docutils\__init__.py changed, reloading.
INFO 2019-07-24 11:04:52,574 autoreload 576 Watching for file changes with StatReloader
INFO 2019-07-24 11:08:15,295 autoreload 576 Watching for file changes with StatReloader
INFO 2019-07-24 11:28:11,124 autoreload 576 Watching for file changes with StatReloader
INFO 2019-07-24 11:30:14,205 autoreload 576 Watching for file changes with StatReloader
INFO 2019-07-24 11:31:48,913 autoreload 203 C:\Anaconda\envs\envtest\Lib\site-packages\django\db\backends\mysql\base.py changed, reloading.
INFO 2019-07-24 11:31:51,382 autoreload 576 Watching for file changes with StatReloader
INFO 2019-07-24 12:34:38,496 autoreload 576 Watching for file changes with StatReloader
INFO 2019-07-24 12:35:39,383 autoreload 203 C:\Anaconda\envs\envtest\Lib\site-packages\docutils\core.py changed, reloading.
INFO 2019-07-24 12:35:40,288 autoreload 576 Watching for file changes with StatReloader
INFO 2019-07-24 12:38:05,896 autoreload 576 Watching for file changes with StatReloader
INFO 2019-07-24 12:38:28,820 autoreload 576 Watching for file changes with StatReloader
INFO 2019-07-24 12:38:37,751 autoreload 203 D:\wxh\mysite\mysite\settings.py changed, reloading.
INFO 2019-07-24 12:38:38,597 autoreload 576 Watching for file changes with StatReloader
INFO 2019-07-24 12:40:44,554 autoreload 576 Watching for file changes with StatReloader
INFO 2019-07-24 12:41:15,021 autoreload 576 Watching for file changes with StatReloader
INFO 2019-07-24 12:41:25,014 autoreload 203 C:\Anaconda\envs\envtest\Lib\site-packages\django\db\backends\mysql\base.py changed, reloading.
INFO 2019-07-24 12:41:25,793 autoreload 576 Watching for file changes with StatReloader
INFO 2019-07-24 12:43:59,104 autoreload 576 Watching for file changes with StatReloader
INFO 2019-07-24 12:48:14,964 autoreload 576 Watching for file changes with StatReloader
INFO 2019-07-24 13:09:41,157 autoreload 586 Watching for file changes with StatReloader
INFO 2019-07-24 13:09:53,543 autoreload 586 Watching for file changes with StatReloader
INFO 2019-07-24 13:11:35,549 autoreload 586 Watching for file changes with StatReloader
WARNING 2019-07-24 13:19:12,901 log 228 Not Found: /
WARNING 2019-07-24 13:19:12,902 basehttp 154 "GET / HTTP/1.1" 404 2242
WARNING 2019-07-24 13:19:13,017 log 228 Not Found: /favicon.ico
WARNING 2019-07-24 13:19:13,017 basehttp 154 "GET /favicon.ico HTTP/1.1" 404 2293
INFO 2019-07-24 13:19:19,842 basehttp 154 "GET /polls/get_man/ HTTP/1.1" 200 7215
INFO 2019-07-24 13:19:24,521 basehttp 154 "GET /polls/ HTTP/1.1" 200 187
INFO 2019-07-24 13:19:24,528 basehttp 154 "GET /static/css/style.css HTTP/1.1" 200 203
INFO 2019-07-24 13:19:24,550 basehttp 154 "GET /static/images/favicon.ico HTTP/1.1" 200 1459819
INFO 2019-07-24 13:19:24,550 basehttp 154 "GET /static/images/background.png HTTP/1.1" 200 1724105
INFO 2019-07-24 13:20:00,681 basehttp 154 "GET /books/search/ HTTP/1.1" 200 257
INFO 2019-07-24 13:20:07,922 basehttp 154 "GET /books/search/?q=%E5%9F%9F%E5%90%8D HTTP/1.1" 200 142
ERROR 2019-07-24 13:20:36,880 log 228 Internal Server Error: /books/search/
Traceback (most recent call last):
  File "C:\Anaconda\envs\tensorflow\lib\site-packages\django\core\handlers\exception.py", line 34, in inner
    response = get_response(request)
  File "C:\Anaconda\envs\tensorflow\lib\site-packages\django\core\handlers\base.py", line 115, in _get_response
    response = self.process_exception_by_middleware(e, request)
  File "C:\Anaconda\envs\tensorflow\lib\site-packages\django\core\handlers\base.py", line 113, in _get_response
    response = wrapped_callback(request, *callback_args, **callback_kwargs)
  File "D:\wxh\mysite\apps\books\views.py", line 22, in search
    conn = get_redis_connection('django')
  File "C:\Anaconda\envs\tensorflow\lib\site-packages\django_redis\__init__.py", line 14, in get_redis_connection
    cache = caches[alias]
  File "C:\Anaconda\envs\tensorflow\lib\site-packages\django\core\cache\__init__.py", line 76, in __getitem__
    "Could not find config for '%s' in settings.CACHES" % alias
django.core.cache.backends.base.InvalidCacheBackendError: Could not find config for 'django' in settings.CACHES
ERROR 2019-07-24 13:20:36,881 basehttp 154 "GET /books/search/?q=%E5%9F%9F%E5%90%8D HTTP/1.1" 500 78153
ERROR 2019-07-24 13:21:19,121 log 228 Internal Server Error: /books/search/
Traceback (most recent call last):
  File "C:\Anaconda\envs\tensorflow\lib\site-packages\django\core\handlers\exception.py", line 34, in inner
    response = get_response(request)
  File "C:\Anaconda\envs\tensorflow\lib\site-packages\django\core\handlers\base.py", line 115, in _get_response
    response = self.process_exception_by_middleware(e, request)
  File "C:\Anaconda\envs\tensorflow\lib\site-packages\django\core\handlers\base.py", line 113, in _get_response
    response = wrapped_callback(request, *callback_args, **callback_kwargs)
  File "D:\wxh\mysite\apps\books\views.py", line 22, in search
    conn = get_redis_connection('django')
  File "C:\Anaconda\envs\tensorflow\lib\site-packages\django_redis\__init__.py", line 14, in get_redis_connection
    cache = caches[alias]
  File "C:\Anaconda\envs\tensorflow\lib\site-packages\django\core\cache\__init__.py", line 76, in __getitem__
    "Could not find config for '%s' in settings.CACHES" % alias
django.core.cache.backends.base.InvalidCacheBackendError: Could not find config for 'django' in settings.CACHES
ERROR 2019-07-24 13:21:19,123 basehttp 154 "GET /books/search/?q=%E5%9F%9F%E5%90%8D HTTP/1.1" 500 78288
INFO 2019-07-24 13:21:23,703 basehttp 154 "GET /books/search/ HTTP/1.1" 200 257
WARNING 2019-07-24 13:21:23,727 log 228 Not Found: /favicon.ico
WARNING 2019-07-24 13:21:23,728 basehttp 154 "GET /favicon.ico HTTP/1.1" 404 2293
ERROR 2019-07-24 13:21:25,832 log 228 Internal Server Error: /books/search/
Traceback (most recent call last):
  File "C:\Anaconda\envs\tensorflow\lib\site-packages\django\core\handlers\exception.py", line 34, in inner
    response = get_response(request)
  File "C:\Anaconda\envs\tensorflow\lib\site-packages\django\core\handlers\base.py", line 115, in _get_response
    response = self.process_exception_by_middleware(e, request)
  File "C:\Anaconda\envs\tensorflow\lib\site-packages\django\core\handlers\base.py", line 113, in _get_response
    response = wrapped_callback(request, *callback_args, **callback_kwargs)
  File "D:\wxh\mysite\apps\books\views.py", line 22, in search
    conn = get_redis_connection('django')
  File "C:\Anaconda\envs\tensorflow\lib\site-packages\django_redis\__init__.py", line 14, in get_redis_connection
    cache = caches[alias]
  File "C:\Anaconda\envs\tensorflow\lib\site-packages\django\core\cache\__init__.py", line 76, in __getitem__
    "Could not find config for '%s' in settings.CACHES" % alias
django.core.cache.backends.base.InvalidCacheBackendError: Could not find config for 'django' in settings.CACHES
ERROR 2019-07-24 13:21:25,833 basehttp 154 "GET /books/search/?q=%E5%9F%9F%E5%90%8D HTTP/1.1" 500 78153
INFO 2019-07-24 13:21:48,633 basehttp 154 "GET /books/search/ HTTP/1.1" 200 257
WARNING 2019-07-24 13:21:48,653 log 228 Not Found: /favicon.ico
WARNING 2019-07-24 13:21:48,654 basehttp 154 "GET /favicon.ico HTTP/1.1" 404 2293
ERROR 2019-07-24 13:21:51,362 log 228 Internal Server Error: /books/search/
Traceback (most recent call last):
  File "C:\Anaconda\envs\tensorflow\lib\site-packages\django\core\handlers\exception.py", line 34, in inner
    response = get_response(request)
  File "C:\Anaconda\envs\tensorflow\lib\site-packages\django\core\handlers\base.py", line 115, in _get_response
    response = self.process_exception_by_middleware(e, request)
  File "C:\Anaconda\envs\tensorflow\lib\site-packages\django\core\handlers\base.py", line 113, in _get_response
    response = wrapped_callback(request, *callback_args, **callback_kwargs)
  File "D:\wxh\mysite\apps\books\views.py", line 22, in search
    conn = get_redis_connection('django')
  File "C:\Anaconda\envs\tensorflow\lib\site-packages\django_redis\__init__.py", line 14, in get_redis_connection
    cache = caches[alias]
  File "C:\Anaconda\envs\tensorflow\lib\site-packages\django\core\cache\__init__.py", line 76, in __getitem__
    "Could not find config for '%s' in settings.CACHES" % alias
django.core.cache.backends.base.InvalidCacheBackendError: Could not find config for 'django' in settings.CACHES
ERROR 2019-07-24 13:21:51,363 basehttp 154 "GET /books/search/?q=%E5%9F%9F%E5%90%8D HTTP/1.1" 500 78153
INFO 2019-07-24 13:22:08,107 basehttp 154 "GET /books/search/ HTTP/1.1" 200 257
WARNING 2019-07-24 13:22:08,126 log 228 Not Found: /favicon.ico
WARNING 2019-07-24 13:22:08,126 basehttp 154 "GET /favicon.ico HTTP/1.1" 404 2293
ERROR 2019-07-24 13:22:10,764 log 228 Internal Server Error: /books/search/
Traceback (most recent call last):
  File "C:\Anaconda\envs\tensorflow\lib\site-packages\django\core\handlers\exception.py", line 34, in inner
    response = get_response(request)
  File "C:\Anaconda\envs\tensorflow\lib\site-packages\django\core\handlers\base.py", line 115, in _get_response
    response = self.process_exception_by_middleware(e, request)
  File "C:\Anaconda\envs\tensorflow\lib\site-packages\django\core\handlers\base.py", line 113, in _get_response
    response = wrapped_callback(request, *callback_args, **callback_kwargs)
  File "D:\wxh\mysite\apps\books\views.py", line 23, in search
    name = conn.set('name', 'zhangsan', 10000).decode('utf-8')
AttributeError: 'bool' object has no attribute 'decode'
ERROR 2019-07-24 13:22:10,765 basehttp 154 "GET /books/search/?q=%E5%9F%9F%E5%90%8D HTTP/1.1" 500 70650
INFO 2019-07-24 13:22:32,598 basehttp 154 "GET /books/search/?q=%E5%9F%9F%E5%90%8D HTTP/1.1" 200 142
INFO 2019-07-24 13:27:42,622 basehttp 154 "GET /admin HTTP/1.1" 301 0
INFO 2019-07-24 13:27:42,647 basehttp 154 "GET /admin/ HTTP/1.1" 302 0
INFO 2019-07-24 13:27:42,670 basehttp 154 "GET /admin/login/?next=/admin/ HTTP/1.1" 200 1829
INFO 2019-07-24 13:27:42,680 basehttp 154 "GET /static/admin/css/login.css HTTP/1.1" 200 1233
INFO 2019-07-24 13:27:42,680 basehttp 154 "GET /static/admin/css/base.css HTTP/1.1" 200 16378
INFO 2019-07-24 13:27:42,682 basehttp 154 "GET /static/admin/css/responsive.css HTTP/1.1" 200 17944
INFO 2019-07-24 13:27:42,943 basehttp 154 "GET /admin/ HTTP/1.1" 302 0
INFO 2019-07-24 13:27:42,958 basehttp 154 "GET /admin/login/?next=/admin/ HTTP/1.1" 200 1829
INFO 2019-07-24 13:27:42,971 basehttp 154 "GET /static/admin/css/fonts.css HTTP/1.1" 200 423
INFO 2019-07-24 13:27:42,998 basehttp 154 "GET /static/admin/fonts/Roboto-Regular-webfont.woff HTTP/1.1" 200 85876
INFO 2019-07-24 13:27:43,004 basehttp 154 "GET /static/admin/fonts/Roboto-Light-webfont.woff HTTP/1.1" 200 85692
INFO 2019-07-24 13:27:45,173 basehttp 154 "POST /admin/login/?next=/admin/ HTTP/1.1" 200 1958
INFO 2019-07-24 13:27:45,197 basehttp 154 "GET /static/admin/fonts/Roboto-Bold-webfont.woff HTTP/1.1" 200 86184
INFO 2019-07-24 13:27:51,793 basehttp 154 "POST /admin/login/?next=/admin/ HTTP/1.1" 200 1962
INFO 2019-07-24 13:27:57,398 basehttp 154 "POST /admin/login/?next=/admin/ HTTP/1.1" 302 0
INFO 2019-07-24 13:27:57,421 basehttp 154 "GET /admin/ HTTP/1.1" 200 6994
INFO 2019-07-24 13:27:57,429 basehttp 154 "GET /static/admin/css/dashboard.css HTTP/1.1" 200 412
INFO 2019-07-24 13:27:57,433 basehttp 154 "GET /static/admin/img/icon-addlink.svg HTTP/1.1" 200 331
INFO 2019-07-24 13:27:57,434 basehttp 154 "GET /static/admin/img/icon-changelink.svg HTTP/1.1" 200 380
INFO 2019-07-24 13:28:02,798 basehttp 154 "GET /admin/ HTTP/1.1" 200 6994
INFO 2019-07-24 13:29:18,976 basehttp 154 "GET /admin/ HTTP/1.1" 200 7004
INFO 2019-07-24 13:29:18,987 basehttp 154 "GET /static/admin/css/base.css HTTP/1.1" 200 16378
INFO 2019-07-24 13:29:18,987 basehttp 154 "GET /static/admin/css/dashboard.css HTTP/1.1" 200 412
INFO 2019-07-24 13:29:18,988 basehttp 154 "GET /static/admin/css/responsive.css HTTP/1.1" 200 17944
INFO 2019-07-24 13:29:18,992 basehttp 154 "GET /static/admin/css/fonts.css HTTP/1.1" 200 423
INFO 2019-07-24 13:29:19,005 basehttp 154 "GET /static/admin/fonts/Roboto-Light-webfont.woff HTTP/1.1" 200 85692
INFO 2019-07-24 13:29:19,007 basehttp 154 "GET /static/admin/img/icon-addlink.svg HTTP/1.1" 200 331
INFO 2019-07-24 13:29:19,007 basehttp 154 "GET /static/admin/img/icon-changelink.svg HTTP/1.1" 200 380
INFO 2019-07-24 13:29:19,007 basehttp 154 "GET /static/admin/fonts/Roboto-Regular-webfont.woff HTTP/1.1" 200 85876
INFO 2019-07-24 13:29:19,008 basehttp 154 "GET /static/admin/fonts/Roboto-Bold-webfont.woff HTTP/1.1" 200 86184
WARNING 2019-07-24 13:29:19,047 log 228 Not Found: /favicon.ico
WARNING 2019-07-24 13:29:19,047 basehttp 154 "GET /favicon.ico HTTP/1.1" 404 2293
INFO 2019-07-24 13:52:12,704 basehttp 154 "GET /admin/ HTTP/1.1" 200 11811
INFO 2019-07-24 13:52:12,713 basehttp 154 "GET /static/admin/simpleui/static/css/style.css HTTP/1.1" 200 12993
INFO 2019-07-24 13:52:12,716 basehttp 154 "GET /static/admin/simpleui/layui/css/layui.css HTTP/1.1" 200 69523
INFO 2019-07-24 13:52:12,718 basehttp 154 "GET /static/admin/simpleui/layui/layui.js HTTP/1.1" 200 5923
INFO 2019-07-24 13:52:12,718 basehttp 154 "GET /static/admin/simpleui/static/js/vip_comm.js HTTP/1.1" 200 10214
INFO 2019-07-24 13:52:12,718 basehttp 154 "GET /static/admin/js/vendor/jquery/jquery.min.js HTTP/1.1" 200 85659
INFO 2019-07-24 13:52:16,545 basehttp 154 "GET /books/search/?q=%E5%9F%9F%E5%90%8D HTTP/1.1" 200 142
WARNING 2019-07-24 13:52:16,621 log 228 Not Found: /favicon.ico
WARNING 2019-07-24 13:52:16,622 basehttp 154 "GET /favicon.ico HTTP/1.1" 404 2293
INFO 2019-07-24 13:52:20,931 basehttp 154 "GET /books/search/ HTTP/1.1" 200 257
INFO 2019-07-24 13:52:23,365 basehttp 154 "GET /books/search/?q=%E5%9F%9F%E5%90%8D HTTP/1.1" 200 142
INFO 2019-07-24 13:53:11,668 basehttp 154 "GET /books/search/?q=%E5%9F%9F%E5%90%8D HTTP/1.1" 200 142
INFO 2019-07-24 13:53:28,691 basehttp 154 "GET /books/search/?q=%E5%9F%9F%E5%90%8D HTTP/1.1" 200 142
ERROR 2019-07-24 13:53:45,317 log 228 Internal Server Error: /books/search/
Traceback (most recent call last):
  File "C:\Anaconda\envs\tensorflow\lib\site-packages\django\core\handlers\exception.py", line 34, in inner
    response = get_response(request)
  File "C:\Anaconda\envs\tensorflow\lib\site-packages\django\core\handlers\base.py", line 115, in _get_response
    response = self.process_exception_by_middleware(e, request)
  File "C:\Anaconda\envs\tensorflow\lib\site-packages\django\core\handlers\base.py", line 113, in _get_response
    response = wrapped_callback(request, *callback_args, **callback_kwargs)
  File "D:\wxh\mysite\apps\books\views.py", line 18, in search
    if request.user.is_authenticated():
TypeError: 'bool' object is not callable
ERROR 2019-07-24 13:53:45,318 basehttp 154 "GET /books/search/?q=%E5%9F%9F%E5%90%8D HTTP/1.1" 500 70721
WARNING 2019-07-24 13:53:45,481 log 228 Not Found: /favicon.ico
WARNING 2019-07-24 13:53:45,481 basehttp 154 "GET /favicon.ico HTTP/1.1" 404 2293
ERROR 2019-07-24 13:53:52,104 log 228 Internal Server Error: /books/search/
Traceback (most recent call last):
  File "C:\Anaconda\envs\tensorflow\lib\site-packages\django\core\handlers\exception.py", line 34, in inner
    response = get_response(request)
  File "C:\Anaconda\envs\tensorflow\lib\site-packages\django\core\handlers\base.py", line 115, in _get_response
    response = self.process_exception_by_middleware(e, request)
  File "C:\Anaconda\envs\tensorflow\lib\site-packages\django\core\handlers\base.py", line 113, in _get_response
    response = wrapped_callback(request, *callback_args, **callback_kwargs)
  File "D:\wxh\mysite\apps\books\views.py", line 18, in search
    if request.user.is_authenticated():
TypeError: 'bool' object is not callable
ERROR 2019-07-24 13:53:52,104 basehttp 154 "GET /books/search/?q=%E5%9F%9F%E5%90%8D HTTP/1.1" 500 70460
ERROR 2019-07-24 13:54:10,861 log 228 Internal Server Error: /books/search/
Traceback (most recent call last):
  File "C:\Anaconda\envs\tensorflow\lib\site-packages\django\core\handlers\exception.py", line 34, in inner
    response = get_response(request)
  File "C:\Anaconda\envs\tensorflow\lib\site-packages\django\core\handlers\base.py", line 115, in _get_response
    response = self.process_exception_by_middleware(e, request)
  File "C:\Anaconda\envs\tensorflow\lib\site-packages\django\core\handlers\base.py", line 113, in _get_response
    response = wrapped_callback(request, *callback_args, **callback_kwargs)
  File "D:\wxh\mysite\apps\books\views.py", line 18, in search
    if not request.user.is_authenticated():
TypeError: 'bool' object is not callable
ERROR 2019-07-24 13:54:10,863 basehttp 154 "GET /books/search/?q=%E5%9F%9F%E5%90%8D HTTP/1.1" 500 70603
ERROR 2019-07-24 13:54:14,003 log 228 Internal Server Error: /books/search/
Traceback (most recent call last):
  File "C:\Anaconda\envs\tensorflow\lib\site-packages\django\core\handlers\exception.py", line 34, in inner
    response = get_response(request)
  File "C:\Anaconda\envs\tensorflow\lib\site-packages\django\core\handlers\base.py", line 115, in _get_response
    response = self.process_exception_by_middleware(e, request)
  File "C:\Anaconda\envs\tensorflow\lib\site-packages\django\core\handlers\base.py", line 113, in _get_response
    response = wrapped_callback(request, *callback_args, **callback_kwargs)
  File "D:\wxh\mysite\apps\books\views.py", line 18, in search
    if not request.user.is_authenticated():
TypeError: 'bool' object is not callable
ERROR 2019-07-24 13:54:14,004 basehttp 154 "GET /books/search/ HTTP/1.1" 500 70016
ERROR 2019-07-24 13:54:55,499 log 228 Internal Server Error: /books/search/
Traceback (most recent call last):
  File "C:\Anaconda\envs\tensorflow\lib\site-packages\django\core\handlers\exception.py", line 34, in inner
    response = get_response(request)
  File "C:\Anaconda\envs\tensorflow\lib\site-packages\django\core\handlers\base.py", line 115, in _get_response
    response = self.process_exception_by_middleware(e, request)
  File "C:\Anaconda\envs\tensorflow\lib\site-packages\django\core\handlers\base.py", line 113, in _get_response
    response = wrapped_callback(request, *callback_args, **callback_kwargs)
  File "D:\wxh\mysite\apps\books\views.py", line 18, in search
TypeError: 'bool' object is not callable
ERROR 2019-07-24 13:54:55,500 basehttp 154 "GET /books/search/ HTTP/1.1" 500 67441
INFO 2019-07-24 13:55:02,912 basehttp 154 "GET /books/search/ HTTP/1.1" 200 257
INFO 2019-07-24 13:55:05,253 basehttp 154 "GET /books/search/?q=%E5%9F%9F%E5%90%8D HTTP/1.1" 200 142
INFO 2019-07-24 14:16:46,748 basehttp 154 "GET /books/search/?q=%E5%9F%9F%E5%90%8D HTTP/1.1" 200 142
INFO 2019-07-25 10:36:36,815 basehttp 154 "GET /admin HTTP/1.1" 301 0
INFO 2019-07-25 10:36:37,457 basehttp 154 "GET /admin/ HTTP/1.1" 200 11811
INFO 2019-07-25 10:36:37,476 basehttp 154 "GET /static/admin/simpleui/static/css/style.css HTTP/1.1" 200 12993
INFO 2019-07-25 10:36:37,479 basehttp 154 "GET /static/admin/simpleui/layui/css/layui.css HTTP/1.1" 200 69523
INFO 2019-07-25 10:36:37,480 basehttp 154 "GET /static/admin/simpleui/layui/layui.js HTTP/1.1" 200 5923
INFO 2019-07-25 10:36:37,481 basehttp 154 "GET /static/admin/simpleui/static/js/vip_comm.js HTTP/1.1" 200 10214
INFO 2019-07-25 10:36:37,481 basehttp 154 "GET /static/admin/js/vendor/jquery/jquery.min.js HTTP/1.1" 200 85659
WARNING 2019-07-25 10:36:47,276 log 228 Not Found: /high/about_page
WARNING 2019-07-25 10:36:47,276 basehttp 154 "GET /high/about_page HTTP/1.1" 404 2305
WARNING 2019-07-25 10:36:47,353 log 228 Not Found: /favicon.ico
WARNING 2019-07-25 10:36:47,353 basehttp 154 "GET /favicon.ico HTTP/1.1" 404 2293
WARNING 2019-07-25 10:36:55,697 log 228 Not Found: /high/about
WARNING 2019-07-25 10:36:55,697 basehttp 154 "GET /high/about HTTP/1.1" 404 2290
ERROR 2019-07-25 10:37:16,629 log 228 Internal Server Error: /high/about
Traceback (most recent call last):
  File "C:\Anaconda\envs\tensorflow\lib\site-packages\django\core\handlers\exception.py", line 34, in inner
    response = get_response(request)
  File "C:\Anaconda\envs\tensorflow\lib\site-packages\django\core\handlers\base.py", line 115, in _get_response
    response = self.process_exception_by_middleware(e, request)
  File "C:\Anaconda\envs\tensorflow\lib\site-packages\django\core\handlers\base.py", line 113, in _get_response
    response = wrapped_callback(request, *callback_args, **callback_kwargs)
TypeError: about_pages() missing 1 required positional argument: 'page'
ERROR 2019-07-25 10:37:16,631 basehttp 154 "GET /high/about HTTP/1.1" 500 66651
INFO 2019-07-25 10:38:02,889 basehttp 154 "GET /high/about HTTP/1.1" 200 165
ERROR 2019-07-25 10:38:39,251 log 228 Internal Server Error: /high/about
Traceback (most recent call last):
  File "C:\Anaconda\envs\tensorflow\lib\site-packages\django\core\handlers\exception.py", line 34, in inner
    response = get_response(request)
  File "C:\Anaconda\envs\tensorflow\lib\site-packages\django\core\handlers\base.py", line 115, in _get_response
    response = self.process_exception_by_middleware(e, request)
  File "C:\Anaconda\envs\tensorflow\lib\site-packages\django\core\handlers\base.py", line 113, in _get_response
    response = wrapped_callback(request, *callback_args, **callback_kwargs)
TypeError: about_pages() missing 1 required positional argument: 'page'
ERROR 2019-07-25 10:38:39,252 basehttp 154 "GET /high/about HTTP/1.1" 500 66651
ERROR 2019-07-25 10:38:44,266 log 228 Internal Server Error: /high/about
Traceback (most recent call last):
  File "C:\Anaconda\envs\tensorflow\lib\site-packages\django\core\handlers\exception.py", line 34, in inner
    response = get_response(request)
  File "C:\Anaconda\envs\tensorflow\lib\site-packages\django\core\handlers\base.py", line 115, in _get_response
    response = self.process_exception_by_middleware(e, request)
  File "C:\Anaconda\envs\tensorflow\lib\site-packages\django\core\handlers\base.py", line 113, in _get_response
    response = wrapped_callback(request, *callback_args, **callback_kwargs)
TypeError: about_pages() missing 1 required positional argument: 'page'
ERROR 2019-07-25 10:38:44,267 basehttp 154 "GET /high/about HTTP/1.1" 500 66777
WARNING 2019-07-25 10:38:44,334 log 228 Not Found: /favicon.ico
WARNING 2019-07-25 10:38:44,334 basehttp 154 "GET /favicon.ico HTTP/1.1" 404 2398
ERROR 2019-07-25 10:38:50,997 log 228 Internal Server Error: /high/about
Traceback (most recent call last):
  File "C:\Anaconda\envs\tensorflow\lib\site-packages\django\core\handlers\exception.py", line 34, in inner
    response = get_response(request)
  File "C:\Anaconda\envs\tensorflow\lib\site-packages\django\core\handlers\base.py", line 115, in _get_response
    response = self.process_exception_by_middleware(e, request)
  File "C:\Anaconda\envs\tensorflow\lib\site-packages\django\core\handlers\base.py", line 113, in _get_response
    response = wrapped_callback(request, *callback_args, **callback_kwargs)
TypeError: about_pages() missing 1 required positional argument: 'page'
ERROR 2019-07-25 10:38:50,998 basehttp 154 "GET /high/about?page=10 HTTP/1.1" 500 66848
INFO 2019-07-25 10:39:13,462 basehttp 154 "GET /high/about HTTP/1.1" 200 165
WARNING 2019-07-25 10:39:52,174 log 228 Not Found: /high/about
WARNING 2019-07-25 10:39:52,174 basehttp 154 "GET /high/about HTTP/1.1" 404 1704
WARNING 2019-07-25 10:43:38,132 log 228 Not Found: /high/about
WARNING 2019-07-25 10:43:38,132 basehttp 154 "GET /high/about HTTP/1.1" 404 1704
WARNING 2019-07-25 10:43:44,545 log 228 Not Found: /high/about
WARNING 2019-07-25 10:43:44,546 basehttp 154 "GET /high/about HTTP/1.1" 404 1704
WARNING 2019-07-25 10:43:44,565 log 228 Not Found: /favicon.ico
WARNING 2019-07-25 10:43:44,566 basehttp 154 "GET /favicon.ico HTTP/1.1" 404 2398
WARNING 2019-07-25 10:43:46,697 log 228 Not Found: /high/about
WARNING 2019-07-25 10:43:46,698 basehttp 154 "GET /high/about HTTP/1.1" 404 1704
WARNING 2019-07-25 10:43:48,189 log 228 Not Found: /high/about
WARNING 2019-07-25 10:43:48,189 basehttp 154 "GET /high/about HTTP/1.1" 404 1704
WARNING 2019-07-25 10:43:48,210 log 228 Not Found: /favicon.ico
WARNING 2019-07-25 10:43:48,210 basehttp 154 "GET /favicon.ico HTTP/1.1" 404 2398
WARNING 2019-07-25 10:43:48,307 log 228 Not Found: /high/about
WARNING 2019-07-25 10:43:48,307 basehttp 154 "GET /high/about HTTP/1.1" 404 1704
WARNING 2019-07-25 10:43:48,328 log 228 Not Found: /favicon.ico
WARNING 2019-07-25 10:43:48,329 basehttp 154 "GET /favicon.ico HTTP/1.1" 404 2398
WARNING 2019-07-25 10:43:48,427 log 228 Not Found: /high/about
WARNING 2019-07-25 10:43:48,428 basehttp 154 "GET /high/about HTTP/1.1" 404 1704
WARNING 2019-07-25 10:43:48,450 log 228 Not Found: /favicon.ico
WARNING 2019-07-25 10:43:48,450 basehttp 154 "GET /favicon.ico HTTP/1.1" 404 2398
INFO 2019-07-25 10:52:50,945 basehttp 154 "GET /high/about HTTP/1.1" 200 165
WARNING 2019-07-25 10:57:11,668 log 228 Not Found: /high/about---a
WARNING 2019-07-25 10:57:11,668 basehttp 154 "GET /high/about---a HTTP/1.1" 404 2459
WARNING 2019-07-25 10:58:35,434 log 228 Not Found: /high/about---a
WARNING 2019-07-25 10:58:35,435 basehttp 154 "GET /high/about---a HTTP/1.1" 404 123
WARNING 2019-07-25 10:58:38,439 log 228 Not Found: /high/about---a
WARNING 2019-07-25 10:58:38,439 basehttp 154 "GET /high/about---a HTTP/1.1" 404 123
WARNING 2019-07-25 10:58:39,143 log 228 Not Found: /high/about---a
WARNING 2019-07-25 10:58:39,143 basehttp 154 "GET /high/about---a HTTP/1.1" 404 123
WARNING 2019-07-25 10:58:39,469 log 228 Not Found: /high/about---a
WARNING 2019-07-25 10:58:39,469 basehttp 154 "GET /high/about---a HTTP/1.1" 404 123
WARNING 2019-07-25 10:58:39,657 log 228 Not Found: /high/about---a
WARNING 2019-07-25 10:58:39,657 basehttp 154 "GET /high/about---a HTTP/1.1" 404 123
WARNING 2019-07-25 10:58:39,852 log 228 Not Found: /high/about---a
WARNING 2019-07-25 10:58:39,852 basehttp 154 "GET /high/about---a HTTP/1.1" 404 123
WARNING 2019-07-25 10:58:40,019 log 228 Not Found: /high/about---a
WARNING 2019-07-25 10:58:40,019 basehttp 154 "GET /high/about---a HTTP/1.1" 404 123
WARNING 2019-07-25 10:58:40,180 log 228 Not Found: /high/about---a
WARNING 2019-07-25 10:58:40,180 basehttp 154 "GET /high/about---a HTTP/1.1" 404 123
WARNING 2019-07-25 10:58:43,816 log 228 Not Found: /high/about---a
WARNING 2019-07-25 10:58:43,816 basehttp 154 "GET /high/about---a HTTP/1.1" 404 123
WARNING 2019-07-25 10:58:43,985 log 228 Not Found: /high/about---a
WARNING 2019-07-25 10:58:43,985 basehttp 154 "GET /high/about---a HTTP/1.1" 404 123
INFO 2019-07-25 10:58:46,040 basehttp 154 "GET /high/about HTTP/1.1" 200 165
WARNING 2019-07-25 10:58:52,550 log 228 Not Found: /high/about111111
WARNING 2019-07-25 10:58:52,550 basehttp 154 "GET /high/about111111 HTTP/1.1" 404 123
WARNING 2019-07-25 10:59:18,576 log 228 Not Found: /high/about111111
WARNING 2019-07-25 10:59:18,576 basehttp 154 "GET /high/about111111 HTTP/1.1" 404 2465
INFO 2019-07-25 10:59:28,893 basehttp 154 "GET /high/about HTTP/1.1" 200 165
ERROR 2019-07-25 15:18:04,053 basehttp 154 "GET /high/image HTTP/1.1" 500 69711
WARNING 2019-07-25 15:18:04,136 log 228 Not Found: /favicon.ico
WARNING 2019-07-25 15:18:04,136 basehttp 154 "GET /favicon.ico HTTP/1.1" 404 2398
ERROR 2019-07-25 15:18:52,340 log 228 Internal Server Error: /high/image
Traceback (most recent call last):
  File "C:\Anaconda\envs\tensorflow\lib\site-packages\django\core\handlers\exception.py", line 34, in inner
    response = get_response(request)
  File "C:\Anaconda\envs\tensorflow\lib\site-packages\django\core\handlers\base.py", line 115, in _get_response
    response = self.process_exception_by_middleware(e, request)
  File "C:\Anaconda\envs\tensorflow\lib\site-packages\django\core\handlers\base.py", line 113, in _get_response
    response = wrapped_callback(request, *callback_args, **callback_kwargs)
  File "D:\wxh\mysite\apps\high\views.py", line 50, in my_image
    image_data = open("307128.jpg", "rb").read()
FileNotFoundError: [Errno 2] No such file or directory: '307128.jpg'
ERROR 2019-07-25 15:18:52,341 basehttp 154 "GET /high/image HTTP/1.1" 500 69700
ERROR 2019-07-25 15:19:06,760 basehttp 154 "GET /high/image HTTP/1.1" 500 69704
ERROR 2019-07-25 15:19:10,113 basehttp 154 "GET /high/image HTTP/1.1" 500 69704
ERROR 2019-07-25 15:24:02,852 log 228 Internal Server Error: /high/image
Traceback (most recent call last):
  File "C:\Anaconda\envs\tensorflow\lib\site-packages\django\core\handlers\exception.py", line 34, in inner
    response = get_response(request)
  File "C:\Anaconda\envs\tensorflow\lib\site-packages\django\core\handlers\base.py", line 115, in _get_response
    response = self.process_exception_by_middleware(e, request)
  File "C:\Anaconda\envs\tensorflow\lib\site-packages\django\core\handlers\base.py", line 113, in _get_response
    response = wrapped_callback(request, *callback_args, **callback_kwargs)
  File "D:\wxh\mysite\apps\high\views.py", line 52, in my_image
    image_data = open('307128.jpg', "rb").read()
FileNotFoundError: [Errno 2] No such file or directory: '307128.jpg'
ERROR 2019-07-25 15:24:02,853 basehttp 154 "GET /high/image HTTP/1.1" 500 69696
ERROR 2019-07-25 15:24:48,044 log 228 Internal Server Error: /high/image
Traceback (most recent call last):
  File "C:\Anaconda\envs\tensorflow\lib\site-packages\django\core\handlers\exception.py", line 34, in inner
    response = get_response(request)
  File "C:\Anaconda\envs\tensorflow\lib\site-packages\django\core\handlers\base.py", line 115, in _get_response
    response = self.process_exception_by_middleware(e, request)
  File "C:\Anaconda\envs\tensorflow\lib\site-packages\django\core\handlers\base.py", line 113, in _get_response
    response = wrapped_callback(request, *callback_args, **callback_kwargs)
  File "D:\wxh\mysite\apps\high\views.py", line 52, in my_image
    image_data = open('images/307128.jpg', "rb").read()
FileNotFoundError: [Errno 2] No such file or directory: 'images/307128.jpg'
ERROR 2019-07-25 15:24:48,046 basehttp 154 "GET /high/image HTTP/1.1" 500 69731
ERROR 2019-07-25 15:25:04,950 log 228 Internal Server Error: /high/image
Traceback (most recent call last):
  File "C:\Anaconda\envs\tensorflow\lib\site-packages\django\core\handlers\exception.py", line 34, in inner
    response = get_response(request)
  File "C:\Anaconda\envs\tensorflow\lib\site-packages\django\core\handlers\base.py", line 115, in _get_response
    response = self.process_exception_by_middleware(e, request)
  File "C:\Anaconda\envs\tensorflow\lib\site-packages\django\core\handlers\base.py", line 113, in _get_response
    response = wrapped_callback(request, *callback_args, **callback_kwargs)
  File "D:\wxh\mysite\apps\high\views.py", line 53, in my_image
    return HttpResponse(image_data, mimetype="image/png")
  File "C:\Anaconda\envs\tensorflow\lib\site-packages\django\http\response.py", line 289, in __init__
    super().__init__(*args, **kwargs)
TypeError: __init__() got an unexpected keyword argument 'mimetype'
ERROR 2019-07-25 15:25:04,951 basehttp 154 "GET /high/image HTTP/1.1" 500 83368
ERROR 2019-07-25 15:25:45,109 log 228 Internal Server Error: /high/image
Traceback (most recent call last):
  File "C:\Anaconda\envs\tensorflow\lib\site-packages\django\core\handlers\exception.py", line 34, in inner
    response = get_response(request)
  File "C:\Anaconda\envs\tensorflow\lib\site-packages\django\core\handlers\base.py", line 115, in _get_response
    response = self.process_exception_by_middleware(e, request)
  File "C:\Anaconda\envs\tensorflow\lib\site-packages\django\core\handlers\base.py", line 113, in _get_response
    response = wrapped_callback(request, *callback_args, **callback_kwargs)
  File "D:\wxh\mysite\apps\high\views.py", line 52, in my_image
    image_data = open('static/images/307128.png', "rb").read()
FileNotFoundError: [Errno 2] No such file or directory: 'static/images/307128.png'
ERROR 2019-07-25 15:25:45,110 basehttp 154 "GET /high/image HTTP/1.1" 500 69766
ERROR 2019-07-25 15:26:21,784 log 228 Internal Server Error: /high/image
Traceback (most recent call last):
  File "C:\Anaconda\envs\tensorflow\lib\site-packages\django\core\handlers\exception.py", line 34, in inner
    response = get_response(request)
  File "C:\Anaconda\envs\tensorflow\lib\site-packages\django\core\handlers\base.py", line 115, in _get_response
    response = self.process_exception_by_middleware(e, request)
  File "C:\Anaconda\envs\tensorflow\lib\site-packages\django\core\handlers\base.py", line 113, in _get_response
    response = wrapped_callback(request, *callback_args, **callback_kwargs)
  File "D:\wxh\mysite\apps\high\views.py", line 53, in my_image
    return HttpResponse(image_data, mimetype="image/png")
  File "C:\Anaconda\envs\tensorflow\lib\site-packages\django\http\response.py", line 289, in __init__
    super().__init__(*args, **kwargs)
TypeError: __init__() got an unexpected keyword argument 'mimetype'
ERROR 2019-07-25 15:26:21,785 basehttp 154 "GET /high/image HTTP/1.1" 500 83368
INFO 2019-07-25 15:26:49,936 basehttp 154 "GET /high/image HTTP/1.1" 200 44672
INFO 2019-07-25 15:27:35,502 basehttp 154 "GET /high/image HTTP/1.1" 200 44672
ERROR 2019-07-25 15:41:36,441 log 228 Internal Server Error: /high/csv
Traceback (most recent call last):
  File "C:\Anaconda\envs\tensorflow\lib\site-packages\django\core\handlers\exception.py", line 34, in inner
    response = get_response(request)
  File "C:\Anaconda\envs\tensorflow\lib\site-packages\django\core\handlers\base.py", line 115, in _get_response
    response = self.process_exception_by_middleware(e, request)
  File "C:\Anaconda\envs\tensorflow\lib\site-packages\django\core\handlers\base.py", line 113, in _get_response
    response = wrapped_callback(request, *callback_args, **callback_kwargs)
  File "D:\wxh\mysite\apps\high\views.py", line 63, in unruly_passengers_csv
    response['Content©\Disposition'] = 'attachment; filename=unruly.csv'
  File "C:\Anaconda\envs\tensorflow\lib\site-packages\django\http\response.py", line 136, in __setitem__
    header = self._convert_to_charset(header, 'ascii')
  File "C:\Anaconda\envs\tensorflow\lib\site-packages\django\http\response.py", line 123, in _convert_to_charset
    value.encode(charset)
UnicodeEncodeError: 'ascii' codec can't encode character '\u2010' in position 7: ordinal not in range(128), HTTP response headers must be in ascii format
ERROR 2019-07-25 15:41:36,442 basehttp 154 "GET /high/csv HTTP/1.1" 500 79841
INFO 2019-07-25 15:43:38,867 basehttp 154 "GET /high/csv HTTP/1.1" 200 142
INFO 2019-07-25 15:46:36,764 basehttp 154 "GET /high/csv HTTP/1.1" 200 142
INFO 2019-07-25 15:46:39,772 basehttp 154 "GET /high/csv HTTP/1.1" 200 142
INFO 2019-07-25 15:46:55,556 basehttp 154 "GET /high/csv HTTP/1.1" 200 142
ERROR 2019-07-25 15:52:05,867 log 228 Internal Server Error: /high/pdf
Traceback (most recent call last):
  File "C:\Anaconda\envs\tensorflow\lib\site-packages\django\core\handlers\exception.py", line 34, in inner
    response = get_response(request)
  File "C:\Anaconda\envs\tensorflow\lib\site-packages\django\core\handlers\base.py", line 115, in _get_response
    response = self.process_exception_by_middleware(e, request)
  File "C:\Anaconda\envs\tensorflow\lib\site-packages\django\core\handlers\base.py", line 113, in _get_response
    response = wrapped_callback(request, *callback_args, **callback_kwargs)
  File "D:\wxh\mysite\apps\high\views.py", line 76, in hello_pdf
    response = HttpResponse(mimetype='application/pdf')
  File "C:\Anaconda\envs\tensorflow\lib\site-packages\django\http\response.py", line 289, in __init__
    super().__init__(*args, **kwargs)
TypeError: __init__() got an unexpected keyword argument 'mimetype'
ERROR 2019-07-25 15:52:05,868 basehttp 154 "GET /high/pdf HTTP/1.1" 500 74932
WARNING 2019-07-25 15:52:05,960 log 228 Not Found: /favicon.ico
WARNING 2019-07-25 15:52:05,961 basehttp 154 "GET /favicon.ico HTTP/1.1" 404 2398
ERROR 2019-07-25 15:52:22,015 log 228 Internal Server Error: /high/pdf
Traceback (most recent call last):
  File "C:\Anaconda\envs\tensorflow\lib\site-packages\django\core\handlers\exception.py", line 34, in inner
    response = get_response(request)
  File "C:\Anaconda\envs\tensorflow\lib\site-packages\django\core\handlers\base.py", line 115, in _get_response
    response = self.process_exception_by_middleware(e, request)
  File "C:\Anaconda\envs\tensorflow\lib\site-packages\django\core\handlers\base.py", line 113, in _get_response
    response = wrapped_callback(request, *callback_args, **callback_kwargs)
  File "D:\wxh\mysite\apps\high\views.py", line 77, in hello_pdf
    response['Content©\Disposition'] = 'attachment; filename=hello.pdf'
  File "C:\Anaconda\envs\tensorflow\lib\site-packages\django\http\response.py", line 136, in __setitem__
    header = self._convert_to_charset(header, 'ascii')
  File "C:\Anaconda\envs\tensorflow\lib\site-packages\django\http\response.py", line 123, in _convert_to_charset
    value.encode(charset)
UnicodeEncodeError: 'ascii' codec can't encode character '\u2010' in position 7: ordinal not in range(128), HTTP response headers must be in ascii format
ERROR 2019-07-25 15:52:22,016 basehttp 154 "GET /high/pdf HTTP/1.1" 500 79936
ERROR 2019-07-25 15:52:41,287 log 228 Internal Server Error: /high/pdf
Traceback (most recent call last):
  File "C:\Anaconda\envs\tensorflow\lib\site-packages\django\core\handlers\exception.py", line 34, in inner
    response = get_response(request)
  File "C:\Anaconda\envs\tensorflow\lib\site-packages\django\core\handlers\base.py", line 115, in _get_response
    response = self.process_exception_by_middleware(e, request)
  File "C:\Anaconda\envs\tensorflow\lib\site-packages\django\core\handlers\base.py", line 113, in _get_response
    response = wrapped_callback(request, *callback_args, **callback_kwargs)
  File "D:\wxh\mysite\apps\high\views.py", line 77, in hello_pdf
    response['Content©\Disposition'] = 'attachment; filename="hello.pdf"'
  File "C:\Anaconda\envs\tensorflow\lib\site-packages\django\http\response.py", line 136, in __setitem__
    header = self._convert_to_charset(header, 'ascii')
  File "C:\Anaconda\envs\tensorflow\lib\site-packages\django\http\response.py", line 123, in _convert_to_charset
    value.encode(charset)
UnicodeEncodeError: 'ascii' codec can't encode character '\u2010' in position 7: ordinal not in range(128), HTTP response headers must be in ascii format
ERROR 2019-07-25 15:52:41,288 basehttp 154 "GET /high/pdf HTTP/1.1" 500 79972
ERROR 2019-07-25 15:52:46,036 log 228 Internal Server Error: /high/pdf
Traceback (most recent call last):
  File "C:\Anaconda\envs\tensorflow\lib\site-packages\django\core\handlers\exception.py", line 34, in inner
    response = get_response(request)
  File "C:\Anaconda\envs\tensorflow\lib\site-packages\django\core\handlers\base.py", line 115, in _get_response
    response = self.process_exception_by_middleware(e, request)
  File "C:\Anaconda\envs\tensorflow\lib\site-packages\django\core\handlers\base.py", line 113, in _get_response
    response = wrapped_callback(request, *callback_args, **callback_kwargs)
  File "D:\wxh\mysite\apps\high\views.py", line 77, in hello_pdf
    response['Content©\Disposition'] = 'attachment; filename="hello.pdf"'
  File "C:\Anaconda\envs\tensorflow\lib\site-packages\django\http\response.py", line 136, in __setitem__
    header = self._convert_to_charset(header, 'ascii')
  File "C:\Anaconda\envs\tensorflow\lib\site-packages\django\http\response.py", line 123, in _convert_to_charset
    value.encode(charset)
UnicodeEncodeError: 'ascii' codec can't encode character '\u2010' in position 7: ordinal not in range(128), HTTP response headers must be in ascii format
ERROR 2019-07-25 15:52:46,037 basehttp 154 "GET /high/pdf HTTP/1.1" 500 80098
WARNING 2019-07-25 15:52:46,109 log 228 Not Found: /favicon.ico
WARNING 2019-07-25 15:52:46,110 basehttp 154 "GET /favicon.ico HTTP/1.1" 404 2398
INFO 2019-07-25 15:53:09,646 basehttp 154 "GET /high/pdf HTTP/1.1" 200 1413
INFO 2019-07-25 16:31:42,923 basehttp 154 "GET /admin HTTP/1.1" 301 0
INFO 2019-07-25 16:31:43,625 basehttp 154 "GET /admin/ HTTP/1.1" 200 11811
INFO 2019-07-25 16:31:43,638 basehttp 154 "GET /static/admin/simpleui/static/css/style.css HTTP/1.1" 200 12993
INFO 2019-07-25 16:31:43,640 basehttp 154 "GET /static/admin/simpleui/layui/css/layui.css HTTP/1.1" 200 69523
INFO 2019-07-25 16:31:43,641 basehttp 154 "GET /static/admin/simpleui/layui/layui.js HTTP/1.1" 200 5923
INFO 2019-07-25 16:31:43,641 basehttp 154 "GET /static/admin/simpleui/static/js/vip_comm.js HTTP/1.1" 200 10214
INFO 2019-07-25 16:31:43,642 basehttp 154 "GET /static/admin/js/vendor/jquery/jquery.min.js HTTP/1.1" 200 85659
INFO 2019-07-25 16:31:45,396 basehttp 154 "GET /admin/books/ HTTP/1.1" 200 6933
INFO 2019-07-25 16:31:45,448 basehttp 154 "GET /static/admin/simpleui/layui/font/iconfont.woff?v=240 HTTP/1.1" 200 26744
INFO 2019-07-25 16:31:45,450 basehttp 154 "GET /static/admin/simpleui/layui/lay/modules/layer.js HTTP/1.1" 200 21834
INFO 2019-07-25 16:31:45,460 basehttp 154 "GET /static/admin/simpleui/layui/lay/modules/element.js HTTP/1.1" 200 6959
INFO 2019-07-25 16:31:45,461 basehttp 154 "GET /static/admin/simpleui/layui/css/modules/layer/default/layer.css?v=3.0.3 HTTP/1.1" 200 14425
INFO 2019-07-25 16:31:45,482 basehttp 154 "GET /static/admin/simpleui/layui/lay/modules/util.js HTTP/1.1" 200 1760
INFO 2019-07-25 16:31:49,840 basehttp 154 "GET /admin/logout HTTP/1.1" 301 0
INFO 2019-07-25 16:31:49,918 basehttp 154 "GET /admin/logout/ HTTP/1.1" 200 161
INFO 2019-07-25 16:31:49,942 basehttp 154 "GET /admin/login/ HTTP/1.1" 200 1893
INFO 2019-07-25 16:31:49,951 basehttp 154 "GET /static/admin/css/ui.css HTTP/1.1" 200 305
INFO 2019-07-25 16:31:49,956 basehttp 154 "GET /static/admin/simpleui/layui/lay/modules/form.js HTTP/1.1" 200 7329
INFO 2019-07-25 16:31:49,966 basehttp 154 "GET /static/admin/simpleui/layui/lay/modules/jquery.js HTTP/1.1" 200 97647
INFO 2019-07-25 16:31:50,000 basehttp 154 "GET /static/admin/simpleui/static/image/code.png HTTP/1.1" 200 2108
INFO 2019-07-25 16:31:58,414 basehttp 154 "POST /admin/login/ HTTP/1.1" 302 0
INFO 2019-07-25 16:31:58,432 basehttp 154 "GET /admin/ HTTP/1.1" 200 11809
INFO 2019-07-25 16:32:45,059 basehttp 154 "GET /admin/logout/ HTTP/1.1" 200 161
INFO 2019-07-25 16:32:45,092 basehttp 154 "GET /admin/login/ HTTP/1.1" 200 1896
INFO 2019-07-25 16:32:47,029 basehttp 154 "POST /admin/login/ HTTP/1.1" 302 0
INFO 2019-07-25 16:32:47,672 basehttp 154 "GET /admin/ HTTP/1.1" 200 11820
INFO 2019-07-25 16:33:14,100 basehttp 154 "GET /admin/ HTTP/1.1" 200 11820
INFO 2019-07-25 16:33:33,085 basehttp 154 "GET /admin/ HTTP/1.1" 200 11809
INFO 2019-07-25 16:35:12,285 basehttp 154 "GET /admin/ HTTP/1.1" 200 11809
INFO 2019-07-25 16:36:29,617 basehttp 154 "GET /admin/ HTTP/1.1" 200 7002
INFO 2019-07-25 16:36:29,628 basehttp 154 "GET /static/admin/css/dashboard.css HTTP/1.1" 200 412
INFO 2019-07-25 16:36:29,629 basehttp 154 "GET /static/admin/css/base.css HTTP/1.1" 200 16378
INFO 2019-07-25 16:36:29,630 basehttp 154 "GET /static/admin/css/responsive.css HTTP/1.1" 200 17944
INFO 2019-07-25 16:36:29,632 basehttp 154 "GET /static/admin/css/fonts.css HTTP/1.1" 200 423
INFO 2019-07-25 16:36:29,641 basehttp 154 "GET /static/admin/img/icon-changelink.svg HTTP/1.1" 200 380
INFO 2019-07-25 16:36:29,641 basehttp 154 "GET /static/admin/img/icon-addlink.svg HTTP/1.1" 200 331
INFO 2019-07-25 16:36:29,691 basehttp 154 "GET /static/admin/fonts/Roboto-Regular-webfont.woff HTTP/1.1" 200 85876
INFO 2019-07-25 16:36:29,692 basehttp 154 "GET /static/admin/fonts/Roboto-Bold-webfont.woff HTTP/1.1" 200 86184
INFO 2019-07-25 16:36:29,692 basehttp 154 "GET /static/admin/fonts/Roboto-Light-webfont.woff HTTP/1.1" 200 85692
ERROR 2019-07-25 17:11:48,912 log 228 Internal Server Error: /high/zhuce
Traceback (most recent call last):
  File "C:\Anaconda\envs\tensorflow\lib\site-packages\django\core\handlers\exception.py", line 34, in inner
    response = get_response(request)
  File "C:\Anaconda\envs\tensorflow\lib\site-packages\django\core\handlers\base.py", line 115, in _get_response
    response = self.process_exception_by_middleware(e, request)
  File "C:\Anaconda\envs\tensorflow\lib\site-packages\django\core\handlers\base.py", line 113, in _get_response
    response = wrapped_callback(request, *callback_args, **callback_kwargs)
  File "D:\wxh\mysite\apps\high\views.py", line 99, in register
    'form': form,
  File "C:\Anaconda\envs\tensorflow\lib\site-packages\django\shortcuts.py", line 36, in render
    content = loader.render_to_string(template_name, context, request, using=using)
  File "C:\Anaconda\envs\tensorflow\lib\site-packages\django\template\loader.py", line 61, in render_to_string
    template = get_template(template_name, using=using)
  File "C:\Anaconda\envs\tensorflow\lib\site-packages\django\template\loader.py", line 15, in get_template
    return engine.get_template(template_name)
  File "C:\Anaconda\envs\tensorflow\lib\site-packages\django\template\backends\django.py", line 34, in get_template
    return Template(self.engine.get_template(template_name), self)
  File "C:\Anaconda\envs\tensorflow\lib\site-packages\django\template\engine.py", line 143, in get_template
    template, origin = self.find_template(template_name)
  File "C:\Anaconda\envs\tensorflow\lib\site-packages\django\template\engine.py", line 125, in find_template
    template = loader.get_template(name, skip=skip)
  File "C:\Anaconda\envs\tensorflow\lib\site-packages\django\template\loaders\base.py", line 18, in get_template
    for origin in self.get_template_sources(template_name):
  File "C:\Anaconda\envs\tensorflow\lib\site-packages\django\template\loaders\filesystem.py", line 36, in get_template_sources
    name = safe_join(template_dir, template_name)
  File "C:\Anaconda\envs\tensorflow\lib\site-packages\django\utils\_os.py", line 32, in safe_join
    final_path = abspath(join(base, *paths))
  File "C:\Anaconda\envs\tensorflow\lib\ntpath.py", line 115, in join
    genericpath._check_arg_types('join', path, *paths)
  File "C:\Anaconda\envs\tensorflow\lib\genericpath.py", line 149, in _check_arg_types
    (funcname, s.__class__.__name__)) from None
TypeError: join() argument must be str or bytes, not 'dict'
ERROR 2019-07-25 17:11:48,914 basehttp 154 "GET /high/zhuce HTTP/1.1" 500 121807
INFO 2019-07-25 17:12:23,809 basehttp 154 "GET /high/zhuce HTTP/1.1" 200 123
INFO 2019-07-25 17:14:11,612 basehttp 154 "GET /high/zhuce HTTP/1.1" 200 997
INFO 2019-07-25 17:14:47,622 basehttp 154 "POST /high/zhuce HTTP/1.1" 302 0
WARNING 2019-07-25 17:14:47,629 log 228 Not Found: /books/
WARNING 2019-07-25 17:14:47,630 basehttp 154 "GET /books/ HTTP/1.1" 404 2637
WARNING 2019-07-25 17:16:45,933 log 228 Not Found: /books/
WARNING 2019-07-25 17:16:45,933 basehttp 154 "GET /books/ HTTP/1.1" 404 2637
INFO 2019-07-25 17:16:47,060 basehttp 154 "GET /high/zhuce HTTP/1.1" 200 997
INFO 2019-07-25 17:16:49,587 basehttp 154 "GET /high/zhuce HTTP/1.1" 200 997
WARNING 2019-07-25 17:16:49,630 log 228 Not Found: /favicon.ico
WARNING 2019-07-25 17:16:49,630 basehttp 154 "GET /favicon.ico HTTP/1.1" 404 2398
INFO 2019-07-25 17:16:49,760 basehttp 154 "GET /high/zhuce HTTP/1.1" 200 997
WARNING 2019-07-25 17:16:49,800 log 228 Not Found: /favicon.ico
WARNING 2019-07-25 17:16:49,801 basehttp 154 "GET /favicon.ico HTTP/1.1" 404 2398
INFO 2019-07-25 17:16:49,926 basehttp 154 "GET /high/zhuce HTTP/1.1" 200 997
WARNING 2019-07-25 17:16:49,965 log 228 Not Found: /favicon.ico
WARNING 2019-07-25 17:16:49,965 basehttp 154 "GET /favicon.ico HTTP/1.1" 404 2398
INFO 2019-07-25 17:17:00,270 basehttp 154 "POST /high/zhuce HTTP/1.1" 302 0
WARNING 2019-07-25 17:17:00,276 log 228 Not Found: /high/high/index
WARNING 2019-07-25 17:17:00,276 basehttp 154 "GET /high/high/index HTTP/1.1" 404 3243
INFO 2019-07-25 17:17:14,979 basehttp 154 "GET /high/zhuce HTTP/1.1" 200 997
INFO 2019-07-25 17:17:23,252 basehttp 154 "POST /high/zhuce HTTP/1.1" 302 0
INFO 2019-07-25 17:17:23,256 basehttp 154 "GET /high/index HTTP/1.1" 200 30
INFO 2019-07-25 17:30:17,967 basehttp 154 "GET /high/zhuce HTTP/1.1" 200 997
INFO 2019-07-26 10:37:41,660 basehttp 154 "GET /high/zhuce HTTP/1.1" 200 997
WARNING 2019-07-26 10:37:41,744 log 228 Not Found: /favicon.ico
WARNING 2019-07-26 10:37:41,745 basehttp 154 "GET /favicon.ico HTTP/1.1" 404 2398
INFO 2019-07-26 10:38:07,648 basehttp 154 "GET /high/pdf HTTP/1.1" 200 1413
INFO 2019-07-26 10:39:45,856 autoreload 586 Watching for file changes with StatReloader
INFO 2019-07-26 10:39:52,425 autoreload 213 D:\wxh\mysite\apps\high\views.py changed, reloading.
INFO 2019-07-26 10:39:53,265 autoreload 586 Watching for file changes with StatReloader
